Workbook

Sheet Interprete_Date
B1: A prescindere da come venga scritta, alla fine ti dice SEMPRE quanti giorni conta l'analisi
A3: Modulo 2
B4: =Progressivo_Giornaliero!A2 -> Dati Aggiornati al 30/07/2026 23:23:23 | D4: Punta qui la data del report
B5: =TRIM(B4) -> Dati Aggiornati al 30/07/2026 23:23:23 | D5: annulla spazi
B6: =MID(B5,20,10) -> 30/07/2026 | D6: Taglia l'orario
B7: =LEFT(B6,2) -> 30
B8: =B7+1 -> 31 | D8: Crea l'indice per il CERCA.V
B10: Creazine Indice per il BRIEFING
B11: Prendo la data della chiusura di ieri e faccio +1
B12: =B7 -> 30
B13: =B12+2 -> 32
B15: La scelta del giorno del Briefing è :
B16: =Kerb_BRIEFING!A1 -> 1
B17: =B16+1 -> 2
B23: =_xlfn.NUMBERVALUE(B22) -> 0 | D23: Numero.valore
B24: =LOWER(B12) -> 30 | D24: minusc(b12)
B25: gen | C25: =IFERROR(FIND(B25,$D$93,1),0) -> 0 | D25: 31 | E25: =IF(C25=0,0,D25) -> 0
B26: feb | C26: =IFERROR(FIND(B26,$D$93,1),0) -> 0 | D26: 29 | E26: =IF(C26=0,0,D26) -> 0
B27: mar | C27: =IFERROR(FIND(B27,$D$93,1),0) -> 0 | D27: 31 | E27: =IF(C27=0,0,D27) -> 0
B28: apr | C28: =IFERROR(FIND(B28,$D$93,1),0) -> 0 | D28: 30 | E28: =IF(C28=0,0,D28) -> 0
B29: mag | C29: =IFERROR(FIND(B29,$D$93,1),0) -> 0 | D29: 31 | E29: =IF(C29=0,0,D29) -> 0
B30: giu | C30: =IFERROR(FIND(B30,$D$93,1),0) -> 0 | D30: 30 | E30: =IF(C30=0,0,D30) -> 0
B31: lug | C31: =IFERROR(FIND(B31,$D$93,1),0) -> 0 | D31: 31 | E31: =IF(C31=0,0,D31) -> 0
B32: ago | C32: =IFERROR(FIND(B32,$D$93,1),0) -> 0 | D32: 31 | E32: =IF(C32=0,0,D32) -> 0
B33: set | C33: =IFERROR(FIND(B33,$D$93,1),0) -> 0 | D33: 30 | E33: =IF(C33=0,0,D33) -> 0
B34: ott | C34: =IFERROR(FIND(B34,$D$93,1),0) -> 0 | D34: 31 | E34: =IF(C34=0,0,D34) -> 0
B35: nov | C35: =IFERROR(FIND(B35,$D$93,1),0) -> 0 | D35: 30 | E35: =IF(C35=0,0,D35) -> 0
B36: dic | C36: =IFERROR(FIND(B36,$D$93,1),0) -> 0 | D36: 31 | E36: =IF(C36=0,0,D36) -> 0
B37: Quanti giorni ha il mese in analisi | E37: =SUM(E25:E36) -> 0
B38: Il Report quanti giorni copre? | E38: =B23 -> 0
B39: Giorni mancanti a fine mese (TOT Mese - Giorni del Report) | E39: =E37-E38 -> 0

Sheet Negozi
B5: ALESSANDRIA | E5: 1 | I5: ALESSANDRIA
B6: ANCONA | E6: 2 | I6: ANCONA
B7: ANZANO XPRESS | E7: 3 | I7: ANZANO XPRESS
B8: ARESE | E8: 4 | I8: ARESE
B9: ASCOLI PICENO | E9: 5 | I9: ASCOLI PICENO
B10: ASTI | E10: 6 | I10: ASTI
B11: AVEZZANO | E11: 7 | I11: AVEZZANO
B12: BARI 1 | E12: 8 | I12: BARI 1
B13: BARI 2 | E13: 9 | I13: BARI 2
B14: BARI BLU | E14: 10 | I14: BARI BLU
B15: BASSANO DEL GRAPPA | E15: 11 | I15: BASSANO DEL GRAPPA
B16: BENEVENTO | E16: 12 | I16: BENEVENTO
... B35: CATANIA 1 | E35: 31 | I35: CATANIA 2
B36: CATANIA 2 | I36: CATANZARO
B37: CATANZARO | I37: CHIETI
B38: CHIETI | I38: CHIVASSO
B39: CHIVASSO | I39: COMO
B40: COMO XPRESS | I40: CONEGLIANO
B41: CONEGLIANO | I41: CORRIDONIA
B42: CORRIDONIA | I42: COSENZA
B43: COSENZA | I43: CREMONA
B44: CREMONA | I44: EMPOLI
B45: CUNEO XPRESS | I45: ERBA XPRESS
B46: EMPOLI | I46: ERBUSCO
B47: ERBA XPRESS | I47: FERRARA
... B155: VIGNATE | I155: VITTUONE
B156: VILLESSE
B157: VITERBO
B158: VITTUONE
B159: AREA 1 - Milano & Surroundings
B160: AREA 2 - Nord Est
B161: AREA 3 - Nord Ovest
B162: AREA 4 - Centro & Sardegna
B163: AREA 5 - Tirrenica & Sicilia
B164: AREA 6 - Sud
B165: AREA SMART
B166: AREA XPRESS
B167: NORD - Loseto
... B169: TOTALE

Sheet Trans Nomenclatura
A1: 1 | B1: 2 | C1: 3 | D1: 4 | E1: 5 | F1: 6 | G1: 7 | H1: 8 | I1: 9 | J1: 10 | K1: 11 | L1: 12 | M1: 13 | N1: 14 | O1: 15 | P1: 16 | Q1: 17 | R1: 18 | S1: 19 | T1: 20 | U1: 21 | V1: 22 | W1: 23 | X1: 24 | Y1: 25
A2: Nome Negozio | B2: Area | C2: Imponibile AC | D2: Imponibile AP | E2: vs AP | F2: Pedonabilità AC | G2: Pedonabilità AP | H2: vs AP | I2: Accessori | J2: Protection | K2: EBIT Polizze | L2: MWService | M2: EBIT MWService | N2: Ready to use PC | O2: Ready to use SMPH | P2: Ready to use 1° Avvio Smph | Q2: Screen Protection | R2: Office | S2: McAfee | T2: Calibrazione | U2: Small Repair | V2: Home Delivery | W2: Stock Over 9 | X2: Stock Over 12 | Y2: Own Brands
A4: =MID(Progressivo_Giornaliero!C16,5,30) -> o Vendita | B4: =Progressivo_Giornaliero!B16 -> Area | C4: =Progressivo_Giornaliero!D16 -> Imponibile AC | D4: =Progressivo_Giornaliero!E16 -> Imponibile AP | E4: =Progressivo_Giornaliero!F16 -> vs AP | F4: =Progressivo_Giornaliero!G16 -> Pedonabilità AC | G4: =Progressivo_Giornaliero!H16 -> Pedonabilità AP | H4: =Progressivo_Giornaliero!I16 -> vs AP | I4: =Progressivo_Giornaliero!J16 -> Accessori | J4: =Progressivo_Giornaliero!K16 -> Protection | ... Y4: =Progressivo_Giornaliero!Z16 -> Own Brands
A5: =MID(Progressivo_Giornaliero!C17,5,30) -> ROMA 4 | B5: =Progressivo_Giornaliero!B17 -> AREA 5 - Tirrenica & Sicilia | C5: =Progressivo_Giornaliero!D17 -> 117003.29 | D5: =Progressivo_Giornaliero!E17 -> 95502.85 | E5: =Progressivo_Giornaliero!F17 -> 21500.44 | F5: =Progressivo_Giornaliero!G17 -> 4060 | G5: =Progressivo_Giornaliero!H17 -> 3618 | H5: =Progressivo_Giornaliero!I17 -> 442 | I5: =Progressivo_Giornaliero!J17 -> 10191.1 | J5: =Progressivo_Giornaliero!K17 -> 7406.91 | ... Y5: =Progressivo_Giornaliero!Z17 -> 3903.96
A6: =MID(Progressivo_Giornaliero!C18,5,30) -> MILANO CERTOSA | B6: =Progressivo_Giornaliero!B18 -> AREA 1 - Milano & Surroundings | C6: =Progressivo_Giornaliero!D18 -> 87798.16 | D6: =Progressivo_Giornaliero!E18 -> 76751.96 | E6: =Progressivo_Giornaliero!F18 -> 11046.2 | F6: =Progressivo_Giornaliero!G18 -> 1384 | G6: =Progressivo_Giornaliero!H18 -> 1746 | H6: =Progressivo_Giornaliero!I18 -> -362 | I6: =Progressivo_Giornaliero!J18 -> 9946.59 | J6: =Progressivo_Giornaliero!K18 -> 4804.67 | ... Y6: =Progressivo_Giornaliero!Z18 -> 2172.15
A7: =MID(Progressivo_Giornaliero!C19,5,30) -> CAGLIARI | B7: =Progressivo_Giornaliero!B19 -> AREA 4 - Centro & Sardegna | C7: =Progressivo_Giornaliero!D19 -> 79025.19 | D7: =Progressivo_Giornaliero!E19 -> 65352.48 | E7: =Progressivo_Giornaliero!F19 -> 13672.71 | F7: =Progressivo_Giornaliero!G19 -> 1331 | G7: =Progressivo_Giornaliero!H19 -> 1390 | H7: =Progressivo_Giornaliero!I19 -> -59 | I7: =Progressivo_Giornaliero!J19 -> 5129.95 | J7: =Progressivo_Giornaliero!K19 -> 3525.32 | ... Y7: =Progressivo_Giornaliero!Z19 -> 2218.66
A8: =MID(Progressivo_Giornaliero!C20,5,30) -> BARI 2 | B8: =Progressivo_Giornaliero!B20 -> AREA 6 - Sud | C8: =Progressivo_Giornaliero!D20 -> 72280.73 | D8: =Progressivo_Giornaliero!E20 -> 40229.34 | E8: =Progressivo_Giornaliero!F20 -> 32051.39 | F8: =Progressivo_Giornaliero!G20 -> 4213 | G8: =Progressivo_Giornaliero!H20 -> 1721 | H8: =Progressivo_Giornaliero!I20 -> 2492 | I8: =Progressivo_Giornaliero!J20 -> 5489.04 | J8: =Progressivo_Giornaliero!K20 -> 3905.67 | ... Y8: =Progressivo_Giornaliero!Z20 -> 4684.36
A9: =MID(Progressivo_Giornaliero!C21,5,30) -> BARI 1 | B9: =Progressivo_Giornaliero!B21 -> AREA 6 - Sud | C9: =Progressivo_Giornaliero!D21 -> 71389.49 | D9: =Progressivo_Giornaliero!E21 -> 63042.11 | E9: =Progressivo_Giornaliero!F21 -> 8347.38 | F9: =Progressivo_Giornaliero!G21 -> 1510 | G9: =Progressivo_Giornaliero!H21 -> 1607 | H9: =Progressivo_Giornaliero!I21 -> -97 | I9: =Progressivo_Giornaliero!J21 -> 5728.51 | J9: =Progressivo_Giornaliero!K21 -> 5923.76 | ... Y9: =Progressivo_Giornaliero!Z21 -> 2811.11
A10: =MID(Progressivo_Giornaliero!C22,5,30) -> BRESCIA 1 | B10: =Progressivo_Giornaliero!B22 -> AREA 2 - Nord Est | C10: =Progressivo_Giornaliero!D22 -> 65418.13 | D10: =Progressivo_Giornaliero!E22 -> 63081.35 | E10: =Progressivo_Giornaliero!F22 -> 2336.78 | F10: =Progressivo_Giornaliero!G22 -> 1140 | G10: =Progressivo_Giornaliero!H22 -> 1095 | H10: =Progressivo_Giornaliero!I22 -> 45 | I10: =Progressivo_Giornaliero!J22 -> 6170.94 | J10: =Progressivo_Giornaliero!K22 -> 4805.67 | ... Y10: =Progressivo_Giornaliero!Z22 -> 1915.11
A11: =MID(Progressivo_Giornaliero!C23,5,30) -> PADOVA 1 | B11: =Progressivo_Giornaliero!B23 -> AREA 2 - Nord Est | C11: =Progressivo_Giornaliero!D23 -> 60824.61 | D11: =Progressivo_Giornaliero!E23 -> 40680.04 | E11: =Progressivo_Giornaliero!F23 -> 20144.57 | F11: =Progressivo_Giornaliero!G23 -> 877 | G11: =Progressivo_Giornaliero!H23 -> 975 | H11: =Progressivo_Giornaliero!I23 -> -98 | I11: =Progressivo_Giornaliero!J23 -> 5405.57 | J11: =Progressivo_Giornaliero!K23 -> 2116.75 | ... Y11: =Progressivo_Giornaliero!Z23 -> 2006.49
A12: =MID(Progressivo_Giornaliero!C24,5,30) -> ROMA 5 | B12: =Progressivo_Giornaliero!B24 -> AREA 5 - Tirrenica & Sicilia | C12: =Progressivo_Giornaliero!D24 -> 60812.92 | D12: =Progressivo_Giornaliero!E24 -> 58879.15 | E12: =Progressivo_Giornaliero!F24 -> 1933.77 | F12: =Progressivo_Giornaliero!G24 -> 1265 | G12: =Progressivo_Giornaliero!H24 -> 1392 | H12: =Progressivo_Giornaliero!I24 -> -127 | I12: =Progressivo_Giornaliero!J24 -> 3576.86 | J12: =Progressivo_Giornaliero!K24 -> 4595.54 | ... Y12: =Progressivo_Giornaliero!Z24 -> 2167.72
A13: =MID(Progressivo_Giornaliero!C25,5,30) -> CARUGATE | B13: =Progressivo_Giornaliero!B25 -> AREA 1 - Milano & Surroundings | C13: =Progressivo_Giornaliero!D25 -> 58983.43 | D13: =Progressivo_Giornaliero!E25 -> 31208.64 | E13: =Progressivo_Giornaliero!F25 -> 27774.79 | F13: =Progressivo_Giornaliero!G25 -> 1655 | G13: =Progressivo_Giornaliero!H25 -> 686 | H13: =Progressivo_Giornaliero!I25 -> 969 | I13: =Progressivo_Giornaliero!J25 -> 3927.06 | J13: =Progressivo_Giornaliero!K25 -> 2233.77 | ... Y13: =Progressivo_Giornaliero!Z25 -> 1381.02
A14: =MID(Progressivo_Giornaliero!C26,5,30) -> TRENTO | B14: =Progressivo_Giornaliero!B26 -> AREA 2 - Nord Est | C14: =Progressivo_Giornaliero!D26 -> 58801.2 | D14: =Progressivo_Giornaliero!E26 -> 102024.75 | E14: =Progressivo_Giornaliero!F26 -> -43223.55 | F14: =Progressivo_Giornaliero!G26 -> 1182 | G14: =Progressivo_Giornaliero!H26 -> 1179 | H14: =Progressivo_Giornaliero!I26 -> 3 | I14: =Progressivo_Giornaliero!J26 -> 5230.93 | J14: =Progressivo_Giornaliero!K26 -> 2009.79 | ... Y14: =Progressivo_Giornaliero!Z26 -> 1797.53
A15: =MID(Progressivo_Giornaliero!C27,5,30) -> GENOVA | B15: =Progressivo_Giornaliero!B27 -> AREA 3 - Nord Ovest | C15: =Progressivo_Giornaliero!D27 -> 57261.94 | D15: =Progressivo_Giornaliero!E27 -> 57721.58 | E15: =Progressivo_Giornaliero!F27 -> -459.64 | F15: =Progressivo_Giornaliero!G27 -> 2733 | G15: =Progressivo_Giornaliero!H27 -> 2441 | H15: =Progressivo_Giornaliero!I27 -> 292 | I15: =Progressivo_Giornaliero!J27 -> 7511 | J15: =Progressivo_Giornaliero!K27 -> 2301.64 | ... Y15: =Progressivo_Giornaliero!Z27 -> 3500.56
... A159: =MID(Progressivo_Giornaliero!C171,5,30) -> PESARO | B159: =Progressivo_Giornaliero!B171 -> AREA 4 - Centro & Sardegna | C159: =Progressivo_Giornaliero!D171 -> 0 | D159: =Progressivo_Giornaliero!E171 -> 14135.95 | E159: =Progressivo_Giornaliero!F171 -> -14135.95 | F159: =Progressivo_Giornaliero!G171 -> 0 | G159: =Progressivo_Giornaliero!H171 -> 0 | H159: =Progressivo_Giornaliero!I171 -> 0 | I159: =Progressivo_Giornaliero!J171 -> 0 | J159: =Progressivo_Giornaliero!K171 -> 0 | ... Y159: =Progressivo_Giornaliero!Z171 -> 0
A160: =MID(Progressivo_Giornaliero!C173,5,30) -> ROMA CASETTA MATTEI XPRS | B160: =Progressivo_Giornaliero!B173 -> AREA XPRESS | C160: =Progressivo_Giornaliero!D173 -> 0 | D160: =Progressivo_Giornaliero!E173 -> 0 | E160: =Progressivo_Giornaliero!F173 -> 0 | F160: =Progressivo_Giornaliero!G173 -> 0 | G160: =Progressivo_Giornaliero!H173 -> 0 | H160: =Progressivo_Giornaliero!I173 -> 0 | I160: =Progressivo_Giornaliero!J173 -> 0 | J160: =Progressivo_Giornaliero!K173 -> 0 | ... Y160: =Progressivo_Giornaliero!Z173 -> 0
A161: =MID(Progressivo_Giornaliero!C174,5,30) | B161: =Progressivo_Giornaliero!B174 -> 0 | C161: =Progressivo_Giornaliero!D174 -> 0 | D161: =Progressivo_Giornaliero!E174 -> 0 | E161: =Progressivo_Giornaliero!F174 -> 0 | F161: =Progressivo_Giornaliero!G174 -> 0 | G161: =Progressivo_Giornaliero!H174 -> 0 | H161: =Progressivo_Giornaliero!I174 -> 0 | I161: =Progressivo_Giornaliero!J174 -> 0 | J161: =Progressivo_Giornaliero!K174 -> 0 | ... Y161: =Progressivo_Giornaliero!Z174 -> 0
A162: =MID(Progressivo_Giornaliero!C175,5,30) | B162: =Progressivo_Giornaliero!B175 -> 0 | C162: =Progressivo_Giornaliero!D175 -> 0 | D162: =Progressivo_Giornaliero!E175 -> 0 | E162: =Progressivo_Giornaliero!F175 -> 0 | F162: =Progressivo_Giornaliero!G175 -> 0 | G162: =Progressivo_Giornaliero!H175 -> 0 | H162: =Progressivo_Giornaliero!I175 -> 0 | I162: =Progressivo_Giornaliero!J175 -> 0 | J162: =Progressivo_Giornaliero!K175 -> 0 | ... Y162: =Progressivo_Giornaliero!Z175 -> 0
A163: =MID(Progressivo_Giornaliero!C176,5,30) | B163: =Progressivo_Giornaliero!B176 -> 0 | C163: =Progressivo_Giornaliero!D176 -> 0 | D163: =Progressivo_Giornaliero!E176 -> 0 | E163: =Progressivo_Giornaliero!F176 -> 0 | F163: =Progressivo_Giornaliero!G176 -> 0 | G163: =Progressivo_Giornaliero!H176 -> 0 | H163: =Progressivo_Giornaliero!I176 -> 0 | I163: =Progressivo_Giornaliero!J176 -> 0 | J163: =Progressivo_Giornaliero!K176 -> 0 | ... Y163: =Progressivo_Giornaliero!Z176 -> 0
A164: =MID(Progressivo_Giornaliero!C177,5,30) | B164: =Progressivo_Giornaliero!B177 -> 0 | C164: =Progressivo_Giornaliero!D177 -> 0 | D164: =Progressivo_Giornaliero!E177 -> 0 | E164: =Progressivo_Giornaliero!F177 -> 0 | F164: =Progressivo_Giornaliero!G177 -> 0 | G164: =Progressivo_Giornaliero!H177 -> 0 | H164: =Progressivo_Giornaliero!I177 -> 0 | I164: =Progressivo_Giornaliero!J177 -> 0 | J164: =Progressivo_Giornaliero!K177 -> 0 | ... Y164: =Progressivo_Giornaliero!Z177 -> 0
A165: =MID(Progressivo_Giornaliero!C178,5,30) | B165: =Progressivo_Giornaliero!B178 -> 0 | C165: =Progressivo_Giornaliero!D178 -> 0 | D165: =Progressivo_Giornaliero!E178 -> 0 | E165: =Progressivo_Giornaliero!F178 -> 0 | F165: =Progressivo_Giornaliero!G178 -> 0 | G165: =Progressivo_Giornaliero!H178 -> 0 | H165: =Progressivo_Giornaliero!I178 -> 0 | I165: =Progressivo_Giornaliero!J178 -> 0 | J165: =Progressivo_Giornaliero!K178 -> 0 | ... Y165: =Progressivo_Giornaliero!Z178 -> 0
A166: =MID(Progressivo_Giornaliero!C179,5,30) | B166: =Progressivo_Giornaliero!B179 -> 0 | C166: =Progressivo_Giornaliero!D179 -> 0 | D166: =Progressivo_Giornaliero!E179 -> 0 | E166: =Progressivo_Giornaliero!F179 -> 0 | F166: =Progressivo_Giornaliero!G179 -> 0 | G166: =Progressivo_Giornaliero!H179 -> 0 | H166: =Progressivo_Giornaliero!I179 -> 0 | I166: =Progressivo_Giornaliero!J179 -> 0 | J166: =Progressivo_Giornaliero!K179 -> 0 | ... Y166: =Progressivo_Giornaliero!Z179 -> 0
A167: =MID(Progressivo_Giornaliero!C180,5,30) | B167: =Progressivo_Giornaliero!B180 -> 0 | C167: =Progressivo_Giornaliero!D180 -> 0 | D167: =Progressivo_Giornaliero!E180 -> 0 | E167: =Progressivo_Giornaliero!F180 -> 0 | F167: =Progressivo_Giornaliero!G180 -> 0 | G167: =Progressivo_Giornaliero!H180 -> 0 | H167: =Progressivo_Giornaliero!I180 -> 0 | I167: =Progressivo_Giornaliero!J180 -> 0 | J167: =Progressivo_Giornaliero!K180 -> 0 | ... Y167: =Progressivo_Giornaliero!Z180 -> 0
A168: =MID(Progressivo_Giornaliero!C181,5,30) | B168: =Progressivo_Giornaliero!B181 -> 0 | C168: =Progressivo_Giornaliero!D181 -> 0 | D168: =Progressivo_Giornaliero!E181 -> 0 | E168: =Progressivo_Giornaliero!F181 -> 0 | F168: =Progressivo_Giornaliero!G181 -> 0 | G168: =Progressivo_Giornaliero!H181 -> 0 | H168: =Progressivo_Giornaliero!I181 -> 0 | I168: =Progressivo_Giornaliero!J181 -> 0 | J168: =Progressivo_Giornaliero!K181 -> 0 | ... Y168: =Progressivo_Giornaliero!Z181 -> 0
A169: =MID(Progressivo_Giornaliero!C182,5,30) | B169: =Progressivo_Giornaliero!B182 -> 0 | C169: =Progressivo_Giornaliero!D182 -> 0 | D169: =Progressivo_Giornaliero!E182 -> 0 | E169: =Progressivo_Giornaliero!F182 -> 0 | F169: =Progressivo_Giornaliero!G182 -> 0 | G169: =Progressivo_Giornaliero!H182 -> 0 | H169: =Progressivo_Giornaliero!I182 -> 0 | I169: =Progressivo_Giornaliero!J182 -> 0 | J169: =Progressivo_Giornaliero!K182 -> 0 | ... Y169: =Progressivo_Giornaliero!Z182 -> 0
A170: =MID(Progressivo_Giornaliero!C183,5,30) | B170: =Progressivo_Giornaliero!B183 -> 0 | C170: =Progressivo_Giornaliero!D183 -> 0 | D170: =Progressivo_Giornaliero!E183 -> 0 | E170: =Progressivo_Giornaliero!F183 -> 0 | F170: =Progressivo_Giornaliero!G183 -> 0 | G170: =Progressivo_Giornaliero!H183 -> 0 | H170: =Progressivo_Giornaliero!I183 -> 0 | I170: =Progressivo_Giornaliero!J183 -> 0 | J170: =Progressivo_Giornaliero!K183 -> 0 | ... Y170: =Progressivo_Giornaliero!Z183 -> 0
A171: =MID(Progressivo_Giornaliero!C184,5,30) | B171: =Progressivo_Giornaliero!B184 -> 0 | C171: =Progressivo_Giornaliero!D184 -> 0 | D171: =Progressivo_Giornaliero!E184 -> 0 | E171: =Progressivo_Giornaliero!F184 -> 0 | F171: =Progressivo_Giornaliero!G184 -> 0 | G171: =Progressivo_Giornaliero!H184 -> 0 | H171: =Progressivo_Giornaliero!I184 -> 0 | I171: =Progressivo_Giornaliero!J184 -> 0 | J171: =Progressivo_Giornaliero!K184 -> 0 | ... Y171: =Progressivo_Giornaliero!Z184 -> 0
... A200: =MID(Progressivo_Giornaliero!C213,5,30) | B200: =Progressivo_Giornaliero!B213 -> 0 | C200: =Progressivo_Giornaliero!D213 -> 0 | D200: =Progressivo_Giornaliero!E213 -> 0 | E200: =Progressivo_Giornaliero!F213 -> 0 | F200: =Progressivo_Giornaliero!G213 -> 0 | G200: =Progressivo_Giornaliero!H213 -> 0 | H200: =Progressivo_Giornaliero!I213 -> 0 | I200: =Progressivo_Giornaliero!J213 -> 0 | J200: =Progressivo_Giornaliero!K213 -> 0 | ... Y200: =Progressivo_Giornaliero!Z213 -> 0

Sheet Kerb_Recovery
B2: BRUGHERIO XPRESS | Y2: Seleziona il negozio
B3: Data | D3: Sales | H3: Protection | O3: MW Services | AA3: McAfee | AE3: Microsoft | AI3: OB
D4: Obiettivo Sales | E4: Actual Sales | F4: Delta | G4: % | I4: Obiettivo EBIT | J4: Actual Sales | K4: Actual EBIT | L4: Delta | M4: % | N4: PEZZI U300 | O4: Obiettivo Sales | P4: Obiettivo EBIT | Q4: Actual Sales | R4: Actual EBIT | S4: Delta | T4: % | U4: Screen Sales | V4: Screen EBIT | W4: PEZZI Screen | X4: EBIT RTU | Y4: EBIT Calibrazioni | Z4: EBIT Altro | AA4: Ob. Pezzi | AB4: Actual | AC4: Delta | AD4: % | AE4: Ob. Pezzi | AF4: Actual | AG4: Delta | AH4: % | AI4: Sales | AJ4: %
B5: 1 | C5: Ago | D5: =VLOOKUP($B$2,BDGT_AREE!$A$1:$FT$239,BDGT_AREE!B$1,0) -> 9587.2461 | E5: =IFERROR(VLOOKUP($B$2,'01'!$A$1:$W$201,2,0),0) -> 0 | F5: =E5-D5 -> -9587.2461 | G5: =IFERROR(F5/D5,0) -> -1 | I5: =VLOOKUP($B$2,BDGT_AREE!$A$1:$FT$239,72,0) -> 454.69043 | J5: =IFERROR(VLOOKUP($B$2,'01'!$A$1:$X$201,3,0),0) -> 0 | K5: =IFERROR(VLOOKUP($B$2,'01'!$A$1:$X$201,4,0),0) -> 0 | L5: =IFERROR(K5-I5,0) -> -454.69043 | M5: =IFERROR(L5/I5,0) -> -1 | N5: =IFERROR(D5*Kerb_Realtime!$CD$3/Kerb_Realtime!$CE$3,0) -> 3.7766304 | O5: =(U5-V5)+P5 -> 142.80487 | P5: =VLOOKUP($B$2,BDGT_AREE!$A$1:$FT$239,37,0) -> 93.622277 | Q5: =IFERROR(VLOOKUP($B$2,'01'!$A$1:$W$201,5,0),0) -> 0 | R5: =IFERROR(VLOOKUP($B$2,'01'!$A$1:$W$201,6,0),0) -> 0 | S5: =R5-P5 -> -93.622277 | T5: =IFERROR(S5/P5,0) -> -1 | U5: =V5*Screen_Margini!$R$7 -> 110.03707 | V5: =P5*Kerb_BRIEFING!$Z$5 -> 60.85448 | W5: =V5/Screen_Margini!$G$17 -> 3.5318909 | X5: =P5*Kerb_BRIEFING!$AB$5 -> 17.788233 | Y5: =P5*Kerb_BRIEFING!$AC$5 -> 8.4260049 | Z5: =P5*Kerb_BRIEFING!$AD$5 -> 6.5535594 | AA5: =VLOOKUP($B$2,BDGT_AREE!$A$1:$FT$239,108,0) -> 1.3660392 | AB5: =IFERROR(VLOOKUP($B$2,'01'!$A$1:$W$201,8,0),0) -> 0 | AC5: =AB5-AA5 -> -1.3660392 | AD5: =IFERROR(AC5/AA5,0) -> -1 | AE5: =VLOOKUP($B$2,BDGT_AREE!$A$1:$FT$239,142,0) -> 0.23225806 | AF5: =IFERROR(VLOOKUP($B$2,'01'!$A$1:$W$201,7,0),0) -> 0 | AG5: =AF5-AE5 -> -0.23225806 | AH5: =IFERROR(AG5/AE5,0) -> -1 | AI5: =IFERROR(VLOOKUP($B$2,'01'!$A$1:$W$201,15,0),0) -> 0 | AJ5: =IFERROR(AI5/E5,0) -> 0
B6: 2 | C6: Ago | D6: =VLOOKUP($B$2,BDGT_AREE!$A$1:$FT$239,BDGT_AREE!C$1,0) -> 8359.1399 | E6: =IFERROR(VLOOKUP($B$2,'02'!$A$1:$W$201,2,0),0) -> 0 | F6: =E6-D6 -> -8359.1399 | G6: =IFERROR(F6/D6,0) -> -1 | I6: =VLOOKUP($B$2,BDGT_AREE!$A$1:$FT$239,73,0) -> 391.71479 | J6: =IFERROR(VLOOKUP($B$2,'02'!$A$1:$X$201,3,0),0) -> 0 | K6: =IFERROR(VLOOKUP($B$2,'02'!$A$1:$X$201,4,0),0) -> 0 | L6: =IFERROR(K6-I6,0) -> -391.71479 | M6: =IFERROR(L6/I6,0) -> -1 | N6: =D6*Kerb_Realtime!$CD$3/Kerb_Realtime!$CE$3 -> 3.292852 | O6: =(U6-V6)+P6 -> 123.02608 | P6: =VLOOKUP($B$2,BDGT_AREE!$A$1:$FT$239,38,0) -> 80.655383 | Q6: =IFERROR(VLOOKUP($B$2,'02'!$A$1:$W$201,5,0),0) -> 0 | R6: =IFERROR(VLOOKUP($B$2,'02'!$A$1:$W$201,6,0),0) -> 0 | S6: =R6-P6 -> -80.655383 | T6: =IFERROR(S6/P6,0) -> -1 | U6: =V6*Screen_Margini!$R$7 -> 94.796691 | V6: =P6*Kerb_BRIEFING!$Z$5 -> 52.425999 | W6: =V6/Screen_Margini!$G$17 -> 3.0427161 | X6: =P6*Kerb_BRIEFING!$AB$5 -> 15.324523 | Y6: =P6*Kerb_BRIEFING!$AC$5 -> 7.2589845 | Z6: =P6*Kerb_BRIEFING!$AD$5 -> 5.6458768 | AA6: =VLOOKUP($B$2,BDGT_AREE!$A$1:$FT$239,108,0) -> 1.3660392 | AB6: =IFERROR(VLOOKUP($B$2,'02'!$A$1:$W$201,8,0),0) -> 0 | AC6: =AB6-AA6 -> -1.3660392 | AD6: =IFERROR(AC6/AA6,0) -> -1 | AE6: =VLOOKUP($B$2,BDGT_AREE!$A$1:$FT$239,142,0) -> 0.23225806 | AF6: =IFERROR(VLOOKUP($B$2,'02'!$A$1:$W$201,7,0),0) -> 0 | AG6: =AF6-AE6 -> -0.23225806 | AH6: =IFERROR(AG6/AE6,0) -> -1 | AI6: =IFERROR(VLOOKUP($B$2,'02'!$A$1:$W$201,15,0),0) -> 0 | AJ6: =IFERROR(AI6/E6,0) -> 0
B7: 3 | C7: Ago | D7: =VLOOKUP($B$2,BDGT_AREE!$A$1:$FT$239,BDGT_AREE!D$1,0) -> 6419.1701 | E7: =IFERROR(VLOOKUP($B$2,'03'!$A$1:$X$201,2,0),0) -> 0 | F7: =E7-D7 -> -6419.1701 | G7: =IFERROR(F7/D7,0) -> -1 | I7: =VLOOKUP($B$2,BDGT_AREE!$A$1:$FT$239,74,0) -> 304.43938 | J7: =IFERROR(VLOOKUP($B$2,'03'!$A$1:$X$201,3,0),0) -> 0 | K7: =IFERROR(VLOOKUP($B$2,'03'!$A$1:$X$201,4,0),0) -> 0 | L7: =IFERROR(K7-I7,0) -> -304.43938 | M7: =IFERROR(L7/I7,0) -> -1 | N7: =D7*Kerb_Realtime!$CD$3/Kerb_Realtime!$CE$3 -> 2.5286545 | O7: =(U7-V7)+P7 -> 95.615438 | P7: =VLOOKUP($B$2,BDGT_AREE!$A$1:$FT$239,39,0) -> 62.685083 | Q7: =IFERROR(VLOOKUP($B$2,'03'!$A$1:$X$201,5,0),0) -> 0 | R7: =IFERROR(VLOOKUP($B$2,'03'!$A$1:$X$201,6,0),0) -> 0 | S7: =R7-P7 -> -62.685083 | T7: =IFERROR(S7/P7,0) -> -1 | U7: =V7*Screen_Margini!$R$7 -> 73.675659 | V7: =P7*Kerb_BRIEFING!$Z$5 -> 40.745304 | W7: =V7/Screen_Margini!$G$17 -> 2.3647884 | X7: =P7*Kerb_BRIEFING!$AB$5 -> 11.910166 | Y7: =P7*Kerb_BRIEFING!$AC$5 -> 5.6416575 | Z7: =P7*Kerb_BRIEFING!$AD$5 -> 4.3879558 | AA7: =VLOOKUP($B$2,BDGT_AREE!$A$1:$FT$239,108,0) -> 1.3660392 | AB7: =IFERROR(VLOOKUP($B$2,'03'!$A$1:$X$201,8,0),0) -> 0 | AC7: =AB7-AA7 -> -1.3660392 | AD7: =IFERROR(AC7/AA7,0) -> -1 | AE7: =VLOOKUP($B$2,BDGT_AREE!$A$1:$FT$239,142,0) -> 0.23225806 | AF7: =IFERROR(VLOOKUP($B$2,'03'!$A$1:$X$201,7,0),0) -> 0 | AG7: =AF7-AE7 -> -0.23225806 | AH7: =IFERROR(AG7/AE7,0) -> -1 | AI7: =IFERROR(VLOOKUP($B$2,'03'!$A$1:$X$201,15,0),0) -> 0 | AJ7: =IFERROR(AI7/E7,0) -> 0
B8: 4 | C8: Ago | D8: =VLOOKUP($B$2,BDGT_AREE!$A$1:$FT$239,BDGT_AREE!E$1,0) -> 6177.8645 | E8: =IFERROR(VLOOKUP($B$2,'04'!$A$1:$X$201,2,0),0) -> 0 | F8: =E8-D8 -> -6177.8645 | G8: =IFERROR(F8/D8,0) -> -1 | I8: =VLOOKUP($B$2,BDGT_AREE!$A$1:$FT$239,75,0) -> 292.99507 | J8: =IFERROR(VLOOKUP($B$2,'04'!$A$1:$X$201,3,0),0) -> 0 | K8: =IFERROR(VLOOKUP($B$2,'04'!$A$1:$X$201,4,0),0) -> 0 | L8: =IFERROR(K8-I8,0) -> -292.99507 | M8: =IFERROR(L8/I8,0) -> -1 | N8: =D8*Kerb_Realtime!$CD$3/Kerb_Realtime!$CE$3 -> 2.4335988 | O8: =(U8-V8)+P8 -> 92.021119 | P8: =VLOOKUP($B$2,BDGT_AREE!$A$1:$FT$239,40,0) -> 60.328663 | Q8: =IFERROR(VLOOKUP($B$2,'04'!$A$1:$X$201,5,0),0) -> 0 | R8: =IFERROR(VLOOKUP($B$2,'04'!$A$1:$X$201,6,0),0) -> 0 | S8: =R8-P8 -> -60.328663 | T8: =IFERROR(S8/P8,0) -> -1 | U8: =V8*Screen_Margini!$R$7 -> 70.906087 | V8: =P8*Kerb_BRIEFING!$Z$5 -> 39.213631 | W8: =V8/Screen_Margini!$G$17 -> 2.2758927 | X8: =P8*Kerb_BRIEFING!$AB$5 -> 11.462446 | Y8: =P8*Kerb_BRIEFING!$AC$5 -> 5.4295797 | Z8: =P8*Kerb_BRIEFING!$AD$5 -> 4.2230064 | AA8: =VLOOKUP($B$2,BDGT_AREE!$A$1:$FT$239,108,0) -> 1.3660392 | AB8: =IFERROR(VLOOKUP($B$2,'04'!$A$1:$X$201,8,0),0) -> 0 | AC8: =AB8-AA8 -> -1.3660392 | AD8: =IFERROR(AC8/AA8,0) -> -1 | AE8: =VLOOKUP($B$2,BDGT_AREE!$A$1:$FT$239,142,0) -> 0.23225806 | AF8: =IFERROR(VLOOKUP($B$2,'04'!$A$1:$X$201,7,0),0) -> 0 | AG8: =AF8-AE8 -> -0.23225806 | AH8: =IFERROR(AG8/AE8,0) -> -1 | AI8: =IFERROR(VLOOKUP($B$2,'04'!$A$1:$X$201,15,0),0) -> 0 | AJ8: =IFERROR(AI8/E8,0) -> 0
B9: 5 | C9: Ago | D9: =VLOOKUP($B$2,BDGT_AREE!$A$1:$FT$239,BDGT_AREE!F$1,0) -> 6145.465 | E9: =IFERROR(VLOOKUP($B$2,'05'!$A$1:$X$201,2,0),0) -> 0 | F9: =E9-D9 -> -6145.465 | G9: =IFERROR(F9/D9,0) -> -1 | I9: =VLOOKUP($B$2,BDGT_AREE!$A$1:$FT$239,76,0) -> 291.45848 | J9: =IFERROR(VLOOKUP($B$2,'05'!$A$1:$X$201,3,0),0) -> 0 | K9: =IFERROR(VLOOKUP($B$2,'05'!$A$1:$X$201,4,0),0) -> 0 | L9: =IFERROR(K9-I9,0) -> -291.45848 | M9: =IFERROR(L9/I9,0) -> -1 | N9: =D9*Kerb_Realtime!$CD$3/Kerb_Realtime!$CE$3 -> 2.420836 | O9: =(U9-V9)+P9 -> 91.53852 | P9: =VLOOKUP($B$2,BDGT_AREE!$A$1:$FT$239,41,0) -> 60.012273 | Q9: =IFERROR(VLOOKUP($B$2,'05'!$A$1:$X$201,5,0),0) -> 0 | R9: =IFERROR(VLOOKUP($B$2,'05'!$A$1:$X$201,6,0),0) -> 0 | S9: =R9-P9 -> -60.012273 | T9: =IFERROR(S9/P9,0) -> -1 | U9: =V9*Screen_Margini!$R$7 -> 70.534225 | V9: =P9*Kerb_BRIEFING!$Z$5 -> 39.007977 | W9: =V9/Screen_Margini!$G$17 -> 2.2639569 | X9: =P9*Kerb_BRIEFING!$AB$5 -> 11.402332 | Y9: =P9*Kerb_BRIEFING!$AC$5 -> 5.4011046 | Z9: =P9*Kerb_BRIEFING!$AD$5 -> 4.2008591 | AA9: =VLOOKUP($B$2,BDGT_AREE!$A$1:$FT$239,108,0) -> 1.3660392 | AB9: =IFERROR(VLOOKUP($B$2,'05'!$A$1:$X$201,8,0),0) -> 0 | AC9: =AB9-AA9 -> -1.3660392 | AD9: =IFERROR(AC9/AA9,0) -> -1 | AE9: =VLOOKUP($B$2,BDGT_AREE!$A$1:$FT$239,142,0) -> 0.23225806 | AF9: =IFERROR(VLOOKUP($B$2,'05'!$A$1:$X$201,7,0),0) -> 0 | AG9: =AF9-AE9 -> -0.23225806 | AH9: =IFERROR(AG9/AE9,0) -> -1 | AI9: =IFERROR(VLOOKUP($B$2,'05'!$A$1:$X$201,15,0),0) -> 0 | AJ9: =IFERROR(AI9/E9,0) -> 0
B10: 6 | C10: Ago | D10: =VLOOKUP($B$2,BDGT_AREE!$A$1:$FT$239,BDGT_AREE!G$1,0) -> 6406.8875 | E10: =IFERROR(VLOOKUP($B$2,'06'!$A$1:$X$201,2,0),0) -> 0 | F10: =E10-D10 -> -6406.8875 | G10: =IFERROR(F10/D10,0) -> -1 | I10: =VLOOKUP($B$2,BDGT_AREE!$A$1:$FT$239,77,0) -> 303.85685 | J10: =IFERROR(VLOOKUP($B$2,'06'!$A$1:$X$201,3,0),0) -> 0 | K10: =IFERROR(VLOOKUP($B$2,'06'!$A$1:$X$201,4,0),0) -> 0 | L10: =IFERROR(K10-I10,0) -> -303.85685 | M10: =IFERROR(L10/I10,0) -> -1 | N10: =D10*Kerb_Realtime!$CD$3/Kerb_Realtime!$CE$3 -> 2.5238161 | O10: =(U10-V10)+P10 -> 95.432485 | P10: =VLOOKUP($B$2,BDGT_AREE!$A$1:$FT$239,42,0) -> 62.56514 | Q10: =IFERROR(VLOOKUP($B$2,'06'!$A$1:$X$201,5,0),0) -> 0 | R10: =IFERROR(VLOOKUP($B$2,'06'!$A$1:$X$201,6,0),0) -> 0 | S10: =R10-P10 -> -62.56514 | T10: =IFERROR(S10/P10,0) -> -1 | U10: =V10*Screen_Margini!$R$7 -> 73.534686 | V10: =P10*Kerb_BRIEFING!$Z$5 -> 40.667341 | W10: =V10/Screen_Margini!$G$17 -> 2.3602636 | X10: =P10*Kerb_BRIEFING!$AB$5 -> 11.887377 | Y10: =P10*Kerb_BRIEFING!$AC$5 -> 5.6308626 | Z10: =P10*Kerb_BRIEFING!$AD$5 -> 4.3795598 | AA10: =VLOOKUP($B$2,BDGT_AREE!$A$1:$FT$239,108,0) -> 1.3660392 | AB10: =IFERROR(VLOOKUP($B$2,'06'!$A$1:$X$201,8,0),0) -> 0 | AC10: =AB10-AA10 -> -1.3660392 | AD10: =IFERROR(AC10/AA10,0) -> -1 | AE10: =VLOOKUP($B$2,BDGT_AREE!$A$1:$FT$239,142,0) -> 0.23225806 | AF10: =IFERROR(VLOOKUP($B$2,'06'!$A$1:$X$201,7,0),0) -> 0 | AG10: =AF10-AE10 -> -0.23225806 | AH10: =IFERROR(AG10/AE10,0) -> -1 | AI10: =IFERROR(VLOOKUP($B$2,'06'!$A$1:$X$201,15,0),0) -> 0 | AJ10: =IFERROR(AI10/E10,0) -> 0
B11: 7 | C11: Ago | D11: =VLOOKUP($B$2,BDGT_AREE!$A$1:$FT$239,BDGT_AREE!H$1,0) -> 6599.7424 | E11: =IFERROR(VLOOKUP($B$2,'07'!$A$1:$X$201,2,0),0) -> 0 | F11: =E11-D11 -> -6599.7424 | G11: =IFERROR(F11/D11,0) -> -1 | I11: =VLOOKUP($B$2,BDGT_AREE!$A$1:$FT$239,78,0) -> 313.00331 | J11: =IFERROR(VLOOKUP($B$2,'07'!$A$1:$X$201,3,0),0) -> 0 | K11: =IFERROR(VLOOKUP($B$2,'07'!$A$1:$X$201,4,0),0) -> 0 | L11: =IFERROR(K11-I11,0) -> -313.00331 | M11: =IFERROR(L11/I11,0) -> -1 | N11: =D11*Kerb_Realtime!$CD$3/Kerb_Realtime!$CE$3 -> 2.599786 | O11: =(U11-V11)+P11 -> 98.305116 | P11: =VLOOKUP($B$2,BDGT_AREE!$A$1:$FT$239,43,0) -> 64.448425 | Q11: =IFERROR(VLOOKUP($B$2,'07'!$A$1:$X$201,5,0),0) -> 0 | R11: =IFERROR(VLOOKUP($B$2,'07'!$A$1:$X$201,6,0),0) -> 0 | S11: =R11-P11 -> -64.448425 | T11: =IFERROR(S11/P11,0) -> -1 | U11: =V11*Screen_Margini!$R$7 -> 75.748168 | V11: =P11*Kerb_BRIEFING!$Z$5 -> 41.891476 | W11: =V11/Screen_Margini!$G$17 -> 2.4313103 | X11: =P11*Kerb_BRIEFING!$AB$5 -> 12.245201 | Y11: =P11*Kerb_BRIEFING!$AC$5 -> 5.8003583 | Z11: =P11*Kerb_BRIEFING!$AD$5 -> 4.5113898 | AA11: =VLOOKUP($B$2,BDGT_AREE!$A$1:$FT$239,108,0) -> 1.3660392 | AB11: =IFERROR(VLOOKUP($B$2,'07'!$A$1:$X$201,8,0),0) -> 0 | AC11: =AB11-AA11 -> -1.3660392 | AD11: =IFERROR(AC11/AA11,0) -> -1 | AE11: =VLOOKUP($B$2,BDGT_AREE!$A$1:$FT$239,142,0) -> 0.23225806 | AF11: =IFERROR(VLOOKUP($B$2,'07'!$A$1:$X$201,7,0),0) -> 0 | AG11: =AF11-AE11 -> -0.23225806 | AH11: =IFERROR(AG11/AE11,0) -> -1 | AI11: =IFERROR(VLOOKUP($B$2,'07'!$A$1:$X$201,15,0),0) -> 0 | AJ11: =IFERROR(AI11/E11,0) -> 0
B12: 8 | C12: Ago | D12: =VLOOKUP($B$2,BDGT_AREE!$A$1:$FT$239,BDGT_AREE!I$1,0) -> 8091.6466 | E12: =IFERROR(VLOOKUP($B$2,'08'!$A$1:$X$201,2,0),0) -> 0 | F12: =E12-D12 -> -8091.6466 | G12: =IFERROR(F12/D12,0) -> -1 | I12: =VLOOKUP($B$2,BDGT_AREE!$A$1:$FT$239,79,0) -> 383.75924 | J12: =IFERROR(VLOOKUP($B$2,'08'!$A$1:$X$201,3,0),0) -> 0 | K12: =IFERROR(VLOOKUP($B$2,'08'!$A$1:$X$201,4,0),0) -> 0 | L12: =IFERROR(K12-I12,0) -> -383.75924 | M12: =IFERROR(L12/I12,0) -> -1 | N12: =D12*Kerb_Realtime!$CD$3/Kerb_Realtime!$CE$3 -> 3.1874804 | O12: =(U12-V12)+P12 -> 120.52747 | P12: =VLOOKUP($B$2,BDGT_AREE!$A$1:$FT$239,44,0) -> 79.017308 | Q12: =IFERROR(VLOOKUP($B$2,'08'!$A$1:$X$201,5,0),0) -> 0 | R12: =IFERROR(VLOOKUP($B$2,'08'!$A$1:$X$201,6,0),0) -> 0 | S12: =R12-P12 -> -79.017308 | T12: =IFERROR(S12/P12,0) -> -1 | U12: =V12*Screen_Margini!$R$7 -> 92.871413 | V12: =P12*Kerb_BRIEFING!$Z$5 -> 51.36125 | W12: =V12/Screen_Margini!$G$17 -> 2.9809199 | X12: =P12*Kerb_BRIEFING!$AB$5 -> 15.013289 | Y12: =P12*Kerb_BRIEFING!$AC$5 -> 7.1115577 | Z12: =P12*Kerb_BRIEFING!$AD$5 -> 5.5312116 | AA12: =VLOOKUP($B$2,BDGT_AREE!$A$1:$FT$239,108,0) -> 1.3660392 | AB12: =IFERROR(VLOOKUP($B$2,'08'!$A$1:$X$201,8,0),0) -> 0 | AC12: =AB12-AA12 -> -1.3660392 | AD12: =IFERROR(AC12/AA12,0) -> -1 | AE12: =VLOOKUP($B$2,BDGT_AREE!$A$1:$FT$239,142,0) -> 0.23225806 | AF12: =IFERROR(VLOOKUP($B$2,'08'!$A$1:$X$201,7,0),0) -> 0 | AG12: =AF12-AE12 -> -0.23225806 | AH12: =IFERROR(AG12/AE12,0) -> -1 | AI12: =IFERROR(VLOOKUP($B$2,'08'!$A$1:$X$201,15,0),0) -> 0 | AJ12: =IFERROR(AI12/E12,0) -> 0
B13: 9 | C13: Ago | D13: =VLOOKUP($B$2,BDGT_AREE!$A$1:$FT$239,BDGT_AREE!J$1,0) -> 7537.0839 | E13: =IFERROR(VLOOKUP($B$2,'09'!$A$1:$X$201,2,0),0) -> 0 | F13: =E13-D13 -> -7537.0839 | G13: =IFERROR(F13/D13,0) -> -1 | I13: =VLOOKUP($B$2,BDGT_AREE!$A$1:$FT$239,80,0) -> 353.19271 | J13: =IFERROR(VLOOKUP($B$2,'09'!$A$1:$X$201,3,0),0) -> 0 | K13: =IFERROR(VLOOKUP($B$2,'09'!$A$1:$X$201,4,0),0) -> 0 | L13: =IFERROR(K13-I13,0) -> -353.19271 | M13: =IFERROR(L13/I13,0) -> -1 | N13: =D13*Kerb_Realtime!$CD$3/Kerb_Realtime!$CE$3 -> 2.9690257 | O13: =(U13-V13)+P13 -> 110.92742 | P13: =VLOOKUP($B$2,BDGT_AREE!$A$1:$FT$239,45,0) -> 72.723557 | Q13: =IFERROR(VLOOKUP($B$2,'09'!$A$1:$X$201,5,0),0) -> 0 | R13: =IFERROR(VLOOKUP($B$2,'09'!$A$1:$X$201,6,0),0) -> 0 | S13: =R13-P13 -> -72.723557 | T13: =IFERROR(S13/P13,0) -> -1 | U13: =V13*Screen_Margini!$R$7 -> 85.474178 | V13: =P13*Kerb_BRIEFING!$Z$5 -> 47.270312 | W13: =V13/Screen_Margini!$G$17 -> 2.7434888 | X13: =P13*Kerb_BRIEFING!$AB$5 -> 13.817476 | Y13: =P13*Kerb_BRIEFING!$AC$5 -> 6.5451201 | Z13: =P13*Kerb_BRIEFING!$AD$5 -> 5.090649 | AA13: =VLOOKUP($B$2,BDGT_AREE!$A$1:$FT$239,108,0) -> 1.3660392 | AB13: =IFERROR(VLOOKUP($B$2,'09'!$A$1:$X$201,8,0),0) -> 0 | AC13: =AB13-AA13 -> -1.3660392 | AD13: =IFERROR(AC13/AA13,0) -> -1 | AE13: =VLOOKUP($B$2,BDGT_AREE!$A$1:$FT$239,142,0) -> 0.23225806 | AF13: =IFERROR(VLOOKUP($B$2,'09'!$A$1:$X$201,7,0),0) -> 0 | AG13: =AF13-AE13 -> -0.23225806 | AH13: =IFERROR(AG13/AE13,0) -> -1 | AI13: =IFERROR(VLOOKUP($B$2,'09'!$A$1:$X$201,15,0),0) -> 0 | AJ13: =IFERROR(AI13/E13,0) -> 0
B14: 10 | C14: Ago | D14: =VLOOKUP($B$2,BDGT_AREE!$A$1:$FT$239,BDGT_AREE!K$1,0) -> 7216.4082 | E14: =IFERROR(VLOOKUP($B$2,'10'!$A$1:$X$201,2,0),0) -> 0 | F14: =E14-D14 -> -7216.4082 | G14: =IFERROR(F14/D14,0) -> -1 | I14: =VLOOKUP($B$2,BDGT_AREE!$A$1:$FT$239,81,0) -> 342.24966 | J14: =IFERROR(VLOOKUP($B$2,'10'!$A$1:$X$201,3,0),0) -> 0 | K14: =IFERROR(VLOOKUP($B$2,'10'!$A$1:$X$201,4,0),0) -> 0 | L14: =IFERROR(K14-I14,0) -> -342.24966 | M14: =IFERROR(L14/I14,0) -> -1 | N14: =D14*Kerb_Realtime!$CD$3/Kerb_Realtime!$CE$3 -> 2.8427044 | O14: =(U14-V14)+P14 -> 107.49054 | P14: =VLOOKUP($B$2,BDGT_AREE!$A$1:$FT$239,46,0) -> 70.470348 | Q14: =IFERROR(VLOOKUP($B$2,'10'!$A$1:$X$201,5,0),0) -> 0 | R14: =IFERROR(VLOOKUP($B$2,'10'!$A$1:$X$201,6,0),0) -> 0 | S14: =R14-P14 -> -70.470348 | T14: =IFERROR(S14/P14,0) -> -1 | U14: =V14*Screen_Margini!$R$7 -> 82.825914 | V14: =P14*Kerb_BRIEFING!$Z$5 -> 45.805726 | W14: =V14/Screen_Margini!$G$17 -> 2.6584867 | X14: =P14*Kerb_BRIEFING!$AB$5 -> 13.389366 | Y14: =P14*Kerb_BRIEFING!$AC$5 -> 6.3423313 | Z14: =P14*Kerb_BRIEFING!$AD$5 -> 4.9329243 | AA14: =VLOOKUP($B$2,BDGT_AREE!$A$1:$FT$239,108,0) -> 1.3660392 | AB14: =IFERROR(VLOOKUP($B$2,'10'!$A$1:$X$201,8,0),0) -> 0 | AC14: =AB14-AA14 -> -1.3660392 | AD14: =IFERROR(AC14/AA14,0) -> -1 | AE14: =VLOOKUP($B$2,BDGT_AREE!$A$1:$FT$239,142,0) -> 0.23225806 | AF14: =IFERROR(VLOOKUP($B$2,'10'!$A$1:$X$201,7,0),0) -> 0 | AG14: =AF14-AE14 -> -0.23225806 | AH14: =IFERROR(AG14/AE14,0) -> -1 | AI14: =IFERROR(VLOOKUP($B$2,'10'!$A$1:$X$201,15,0),0) -> 0 | AJ14: =IFERROR(AI14/E14,0) -> 0
B15: 11 | C15: Ago | D15: =VLOOKUP($B$2,BDGT_AREE!$A$1:$FT$239,BDGT_AREE!L$1,0) -> 6942.6788 | E15: =IFERROR(VLOOKUP($B$2,'11'!$A$1:$X$201,2,0),0) -> 0 | F15: =E15-D15 -> -6942.6788 | G15: =IFERROR(F15/D15,0) -> -1 | I15: =VLOOKUP($B$2,BDGT_AREE!$A$1:$FT$239,82,0) -> 329.26761 | J15: =IFERROR(VLOOKUP($B$2,'11'!$A$1:$Y$201,3,0),0) -> 0 | K15: =IFERROR(VLOOKUP($B$2,'11'!$A$1:$Y$201,4,0),0) -> 0 | L15: =IFERROR(K15-I15,0) -> -329.26761 | M15: =IFERROR(L15/I15,0) -> -1 | N15: =D15*Kerb_Realtime!$CD$3/Kerb_Realtime!$CE$3 -> 2.7348763 | O15: =(U15-V15)+P15 -> 103.41326 | P15: =VLOOKUP($B$2,BDGT_AREE!$A$1:$FT$239,47,0) -> 67.7973 | Q15: =IFERROR(VLOOKUP($B$2,'11'!$A$1:$X$201,5,0),0) -> 0 | R15: =IFERROR(VLOOKUP($B$2,'11'!$A$1:$X$201,6,0),0) -> 0 | S15: =R15-P15 -> -67.7973 | T15: =IFERROR(S15/P15,0) -> -1 | U15: =V15*Screen_Margini!$R$7 -> 79.684201 | V15: =P15*Kerb_BRIEFING!$Z$5 -> 44.068245 | W15: =V15/Screen_Margini!$G$17 -> 2.5576463 | X15: =P15*Kerb_BRIEFING!$AB$5 -> 12.881487 | Y15: =P15*Kerb_BRIEFING!$AC$5 -> 6.101757 | Z15: =P15*Kerb_BRIEFING!$AD$5 -> 4.745811 | AA15: =VLOOKUP($B$2,BDGT_AREE!$A$1:$FT$239,108,0) -> 1.3660392 | AB15: =IFERROR(VLOOKUP($B$2,'11'!$A$1:$X$201,8,0),0) -> 0 | AC15: =AB15-AA15 -> -1.3660392 | AD15: =IFERROR(AC15/AA15,0) -> -1 | AE15: =VLOOKUP($B$2,BDGT_AREE!$A$1:$FT$239,142,0) -> 0.23225806 | AF15: =IFERROR(VLOOKUP($B$2,'11'!$A$1:$X$201,7,0),0) -> 0 | AG15: =AF15-AE15 -> -0.23225806 | AH15: =IFERROR(AG15/AE15,0) -> -1 | AI15: =IFERROR(VLOOKUP($B$2,'11'!$A$1:$X$201,15,0),0) -> 0 | AJ15: =IFERROR(AI15/E15,0) -> 0
B16: 12 | C16: Ago | D16: =VLOOKUP($B$2,BDGT_AREE!$A$1:$FT$239,BDGT_AREE!M$1,0) -> 6973.1354 | E16: =IFERROR(VLOOKUP($B$2,'12'!$A$1:$X$201,2,0),0) -> 0 | F16: =E16-D16 -> -6973.1354 | G16: =IFERROR(F16/D16,0) -> -1 | I16: =VLOOKUP($B$2,BDGT_AREE!$A$1:$FT$239,83,0) -> 330.71207 | J16: =IFERROR(VLOOKUP($B$2,'12'!$A$1:$Y$201,3,0),0) -> 0 | K16: =IFERROR(VLOOKUP($B$2,'12'!$A$1:$Y$201,4,0),0) -> 0 | L16: =IFERROR(K16-I16,0) -> -330.71207 | M16: =IFERROR(L16/I16,0) -> -1 | N16: =D16*Kerb_Realtime!$CD$3/Kerb_Realtime!$CE$3 -> 2.7468738 | O16: =(U16-V16)+P16 -> 103.86692 | P16: =VLOOKUP($B$2,BDGT_AREE!$A$1:$FT$239,48,0) -> 68.094717 | Q16: =IFERROR(VLOOKUP($B$2,'12'!$A$1:$X$201,5,0),0) -> 0 | R16: =IFERROR(VLOOKUP($B$2,'12'!$A$1:$X$201,6,0),0) -> 0 | S16: =R16-P16 -> -68.094717 | T16: =IFERROR(S16/P16,0) -> -1 | U16: =V16*Screen_Margini!$R$7 -> 80.033764 | V16: =P16*Kerb_BRIEFING!$Z$5 -> 44.261566 | W16: =V16/Screen_Margini!$G$17 -> 2.5688663 | X16: =P16*Kerb_BRIEFING!$AB$5 -> 12.937996 | Y16: =P16*Kerb_BRIEFING!$AC$5 -> 6.1285246 | Z16: =P16*Kerb_BRIEFING!$AD$5 -> 4.7666302 | AA16: =VLOOKUP($B$2,BDGT_AREE!$A$1:$FT$239,108,0) -> 1.3660392 | AB16: =IFERROR(VLOOKUP($B$2,'12'!$A$1:$X$201,8,0),0) -> 0 | AC16: =AB16-AA16 -> -1.3660392 | AD16: =IFERROR(AC16/AA16,0) -> -1 | AE16: =VLOOKUP($B$2,BDGT_AREE!$A$1:$FT$239,142,0) -> 0.23225806 | AF16: =IFERROR(VLOOKUP($B$2,'12'!$A$1:$X$201,7,0),0) -> 0 | AG16: =AF16-AE16 -> -0.23225806 | AH16: =IFERROR(AG16/AE16,0) -> -1 | AI16: =IFERROR(VLOOKUP($B$2,'12'!$A$1:$X$201,15,0),0) -> 0 | AJ16: =IFERROR(AI16/E16,0) -> 0
B17: 13 | C17: Ago | D17: =VLOOKUP($B$2,BDGT_AREE!$A$1:$FT$239,BDGT_AREE!N$1,0) -> 7257.9788 | E17: =IFERROR(VLOOKUP($B$2,'13'!$A$1:$X$201,2,0),0) -> 0 | F17: =E17-D17 -> -7257.9788 | G17: =IFERROR(F17/D17,0) -> -1 | I17: =VLOOKUP($B$2,BDGT_AREE!$A$1:$FT$239,84,0) -> 344.22122 | J17: =IFERROR(VLOOKUP($B$2,'13'!$A$1:$Y$201,3,0),0) -> 0 | K17: =IFERROR(VLOOKUP($B$2,'13'!$A$1:$Y$201,4,0),0) -> 0 | L17: =IFERROR(K17-I17,0) -> -344.22122 | M17: =IFERROR(L17/I17,0) -> -1 | N17: =D17*Kerb_Realtime!$CD$3/Kerb_Realtime!$CE$3 -> 2.85908 | O17: =(U17-V17)+P17 -> 108.10974 | P17: =VLOOKUP($B$2,BDGT_AREE!$A$1:$FT$239,49,0) -> 70.876297 | Q17: =IFERROR(VLOOKUP($B$2,'13'!$A$1:$X$201,5,0),0) -> 0 | R17: =IFERROR(VLOOKUP($B$2,'13'!$A$1:$X$201,6,0),0) -> 0 | S17: =R17-P17 -> -70.876297 | T17: =IFERROR(S17/P17,0) -> -1 | U17: =V17*Screen_Margini!$R$7 -> 83.303038 | V17: =P17*Kerb_BRIEFING!$Z$5 -> 46.069593 | W17: =V17/Screen_Margini!$G$17 -> 2.6738011 | X17: =P17*Kerb_BRIEFING!$AB$5 -> 13.466496 | Y17: =P17*Kerb_BRIEFING!$AC$5 -> 6.3788667 | Z17: =P17*Kerb_BRIEFING!$AD$5 -> 4.9613408 | AA17: =VLOOKUP($B$2,BDGT_AREE!$A$1:$FT$239,108,0) -> 1.3660392 | AB17: =IFERROR(VLOOKUP($B$2,'13'!$A$1:$X$201,8,0),0) -> 0 | AC17: =AB17-AA17 -> -1.3660392 | AD17: =IFERROR(AC17/AA17,0) -> -1 | AE17: =VLOOKUP($B$2,BDGT_AREE!$A$1:$FT$239,142,0) -> 0.23225806 | AF17: =IFERROR(VLOOKUP($B$2,'13'!$A$1:$X$201,7,0),0) -> 0 | AG17: =AF17-AE17 -> -0.23225806 | AH17: =IFERROR(AG17/AE17,0) -> -1 | AI17: =IFERROR(VLOOKUP($B$2,'13'!$A$1:$X$201,15,0),0) -> 0 | AJ17: =IFERROR(AI17/E17,0) -> 0
B18: 14 | C18: Ago | D18: =VLOOKUP($B$2,BDGT_AREE!$A$1:$FT$239,BDGT_AREE!O$1,0) -> 7381.314 | E18: =IFERROR(VLOOKUP($B$2,'14'!$A$1:$X$201,2,0),0) -> 0 | F18: =E18-D18 -> -7381.314 | G18: =IFERROR(F18/D18,0) -> -1 | I18: =VLOOKUP($B$2,BDGT_AREE!$A$1:$FT$239,85,0) -> 350.07058 | J18: =IFERROR(VLOOKUP($B$2,'14'!$A$1:$Y$201,3,0),0) -> 0 | K18: =IFERROR(VLOOKUP($B$2,'14'!$A$1:$Y$201,4,0),0) -> 0 | L18: =IFERROR(K18-I18,0) -> -350.07058 | M18: =IFERROR(L18/I18,0) -> -1 | N18: =D18*Kerb_Realtime!$CD$3/Kerb_Realtime!$CE$3 -> 2.9076645 | O18: =(U18-V18)+P18 -> 109.94686 | P18: =VLOOKUP($B$2,BDGT_AREE!$A$1:$FT$239,50,0) -> 72.080701 | Q18: =IFERROR(VLOOKUP($B$2,'14'!$A$1:$X$201,5,0),0) -> 0 | R18: =IFERROR(VLOOKUP($B$2,'14'!$A$1:$X$201,6,0),0) -> 0 | S18: =R18-P18 -> -72.080701 | T18: =IFERROR(S18/P18,0) -> -1 | U18: =V18*Screen_Margini!$R$7 -> 84.71861 | V18: =P18*Kerb_BRIEFING!$Z$5 -> 46.852456 | W18: =V18/Screen_Margini!$G$17 -> 2.7192371 | X18: =P18*Kerb_BRIEFING!$AB$5 -> 13.695333 | Y18: =P18*Kerb_BRIEFING!$AC$5 -> 6.4872631 | Z18: =P18*Kerb_BRIEFING!$AD$5 -> 5.0456491 | AA18: =VLOOKUP($B$2,BDGT_AREE!$A$1:$FT$239,108,0) -> 1.3660392 | AB18: =IFERROR(VLOOKUP($B$2,'14'!$A$1:$X$201,8,0),0) -> 0 | AC18: =AB18-AA18 -> -1.3660392 | AD18: =IFERROR(AC18/AA18,0) -> -1 | AE18: =VLOOKUP($B$2,BDGT_AREE!$A$1:$FT$239,142,0) -> 0.23225806 | AF18: =IFERROR(VLOOKUP($B$2,'14'!$A$1:$X$201,7,0),0) -> 0 | AG18: =AF18-AE18 -> -0.23225806 | AH18: =IFERROR(AG18/AE18,0) -> -1 | AI18: =IFERROR(VLOOKUP($B$2,'14'!$A$1:$X$201,15,0),0) -> 0 | AJ18: =IFERROR(AI18/E18,0) -> 0
B19: 15 | C19: Ago | D19: =VLOOKUP($B$2,BDGT_AREE!$A$1:$FT$239,BDGT_AREE!P$1,0) -> 2428.7127 | E19: =IFERROR(VLOOKUP($B$2,'15'!$A$1:$X$201,2,0),0) -> 0 | F19: =E19-D19 -> -2428.7127 | G19: =IFERROR(F19/D19,0) -> -1 | I19: =VLOOKUP($B$2,BDGT_AREE!$A$1:$FT$239,86,0) -> 52.468384 | J19: =IFERROR(VLOOKUP($B$2,'15'!$A$1:$Y$201,3,0),0) -> 0 | K19: =IFERROR(VLOOKUP($B$2,'15'!$A$1:$Y$201,4,0),0) -> 0 | L19: =IFERROR(K19-I19,0) -> -52.468384 | M19: =IFERROR(L19/I19,0) -> -1 | N19: =D19*Kerb_Realtime!$CD$3/Kerb_Realtime!$CE$3 -> 0.9567242 | O19: =(U19-V19)+P19 -> 16.478774 | P19: =VLOOKUP($B$2,BDGT_AREE!$A$1:$FT$239,51,0) -> 10.803415 | Q19: =IFERROR(VLOOKUP($B$2,'15'!$A$1:$X$201,5,0),0) -> 0 | R19: =IFERROR(VLOOKUP($B$2,'15'!$A$1:$X$201,6,0),0) -> 0 | S19: =R19-P19 -> -10.803415 | T19: =IFERROR(S19/P19,0) -> -1 | U19: =V19*Screen_Margini!$R$7 -> 12.697578 | V19: =P19*Kerb_BRIEFING!$Z$5 -> 7.02222 | W19: =V19/Screen_Margini!$G$17 -> 0.40755775 | X19: =P19*Kerb_BRIEFING!$AB$5 -> 2.0526489 | Y19: =P19*Kerb_BRIEFING!$AC$5 -> 0.97230738 | Z19: =P19*Kerb_BRIEFING!$AD$5 -> 0.75623907 | AA19: =VLOOKUP($B$2,BDGT_AREE!$A$1:$FT$239,108,0) -> 1.3660392 | AB19: =IFERROR(VLOOKUP($B$2,'15'!$A$1:$X$201,8,0),0) -> 0 | AC19: =AB19-AA19 -> -1.3660392 | AD19: =IFERROR(AC19/AA19,0) -> -1 | AE19: =VLOOKUP($B$2,BDGT_AREE!$A$1:$FT$239,142,0) -> 0.23225806 | AF19: =IFERROR(VLOOKUP($B$2,'15'!$A$1:$X$201,7,0),0) -> 0 | AG19: =AF19-AE19 -> -0.23225806 | AH19: =IFERROR(AG19/AE19,0) -> -1 | AI19: =IFERROR(VLOOKUP($B$2,'15'!$A$1:$X$201,15,0),0) -> 0 | AJ19: =IFERROR(AI19/E19,0) -> 0
B20: 16 | C20: Ago | D20: =VLOOKUP($B$2,BDGT_AREE!$A$1:$FT$239,BDGT_AREE!Q$1,0) -> 6893.3337 | E20: =IFERROR(VLOOKUP($B$2,'16'!$A$1:$W$201,2,0),0) -> 0 | F20: =E20-D20 -> -6893.3337 | G20: =IFERROR(F20/D20,0) -> -1 | I20: =VLOOKUP($B$2,BDGT_AREE!$A$1:$FT$239,87,0) -> 323.02615 | J20: =IFERROR(VLOOKUP($B$2,'16'!$A$1:$X$201,3,0),0) -> 0 | K20: =IFERROR(VLOOKUP($B$2,'16'!$A$1:$X$201,4,0),0) -> 0 | L20: =IFERROR(K20-I20,0) -> -323.02615 | M20: =IFERROR(L20/I20,0) -> -1 | N20: =D20*Kerb_Realtime!$CD$3/Kerb_Realtime!$CE$3 -> 2.7154382 | O20: =(U20-V20)+P20 -> 101.453 | P20: =VLOOKUP($B$2,BDGT_AREE!$A$1:$FT$239,52,0) -> 66.512162 | Q20: =IFERROR(VLOOKUP($B$2,'16'!$A$1:$W$201,5,0),0) -> 0 | R20: =IFERROR(VLOOKUP($B$2,'16'!$A$1:$W$201,6,0),0) -> 0 | S20: =R20-P20 -> -66.512162 | T20: =IFERROR(S20/P20,0) -> -1 | U20: =V20*Screen_Margini!$R$7 -> 78.17374 | V20: =P20*Kerb_BRIEFING!$Z$5 -> 43.232906 | W20: =V20/Screen_Margini!$G$17 -> 2.5091646 | X20: =P20*Kerb_BRIEFING!$AB$5 -> 12.637311 | Y20: =P20*Kerb_BRIEFING!$AC$5 -> 5.9860946 | Z20: =P20*Kerb_BRIEFING!$AD$5 -> 4.6558514 | AA20: =VLOOKUP($B$2,BDGT_AREE!$A$1:$FT$239,108,0) -> 1.3660392 | AB20: =IFERROR(VLOOKUP($B$2,'16'!$A$1:$W$201,8,0),0) -> 0 | AC20: =AB20-AA20 -> -1.3660392 | AD20: =IFERROR(AC20/AA20,0) -> -1 | AE20: =VLOOKUP($B$2,BDGT_AREE!$A$1:$FT$239,142,0) -> 0.23225806 | AF20: =IFERROR(VLOOKUP($B$2,'16'!$A$1:$W$201,7,0),0) -> 0 | AG20: =AF20-AE20 -> -0.23225806 | AH20: =IFERROR(AG20/AE20,0) -> -1 | AI20: =IFERROR(VLOOKUP($B$2,'16'!$A$1:$W$201,15,0),0) -> 0 | AJ20: =IFERROR(AI20/E20,0) -> 0
B21: 17 | C21: Ago | D21: =VLOOKUP($B$2,BDGT_AREE!$A$1:$FT$239,BDGT_AREE!R$1,0) -> 7528.8612 | E21: =IFERROR(VLOOKUP($B$2,'17'!$A$1:$W$201,2,0),0) -> 0 | F21: =E21-D21 -> -7528.8612 | G21: =IFERROR(F21/D21,0) -> -1 | I21: =VLOOKUP($B$2,BDGT_AREE!$A$1:$FT$239,88,0) -> 357.06825 | J21: =IFERROR(VLOOKUP($B$2,'17'!$A$1:$X$201,3,0),0) -> 0 | K21: =IFERROR(VLOOKUP($B$2,'17'!$A$1:$X$201,4,0),0) -> 0 | L21: =IFERROR(K21-I21,0) -> -357.06825 | M21: =IFERROR(L21/I21,0) -> -1 | N21: =D21*Kerb_Realtime!$CD$3/Kerb_Realtime!$CE$3 -> 2.9657866 | O21: =(U21-V21)+P21 -> 112.14462 | P21: =VLOOKUP($B$2,BDGT_AREE!$A$1:$FT$239,53,0) -> 73.521544 | Q21: =IFERROR(VLOOKUP($B$2,'17'!$A$1:$W$201,5,0),0) -> 0 | R21: =IFERROR(VLOOKUP($B$2,'17'!$A$1:$W$201,6,0),0) -> 0 | S21: =R21-P21 -> -73.521544 | T21: =IFERROR(S21/P21,0) -> -1 | U21: =V21*Screen_Margini!$R$7 -> 86.412076 | V21: =P21*Kerb_BRIEFING!$Z$5 -> 47.789003 | W21: =V21/Screen_Margini!$G$17 -> 2.7735928 | X21: =P21*Kerb_BRIEFING!$AB$5 -> 13.969093 | Y21: =P21*Kerb_BRIEFING!$AC$5 -> 6.6169389 | Z21: =P21*Kerb_BRIEFING!$AD$5 -> 5.1465081 | AA21: =VLOOKUP($B$2,BDGT_AREE!$A$1:$FT$239,108,0) -> 1.3660392 | AB21: =IFERROR(VLOOKUP($B$2,'17'!$A$1:$W$201,8,0),0) -> 0 | AC21: =AB21-AA21 -> -1.3660392 | AD21: =IFERROR(AC21/AA21,0) -> -1 | AE21: =VLOOKUP($B$2,BDGT_AREE!$A$1:$FT$239,142,0) -> 0.23225806 | AF21: =IFERROR(VLOOKUP($B$2,'17'!$A$1:$W$201,7,0),0) -> 0 | AG21: =AF21-AE21 -> -0.23225806 | AH21: =IFERROR(AG21/AE21,0) -> -1 | AI21: =IFERROR(VLOOKUP($B$2,'17'!$A$1:$W$201,15,0),0) -> 0 | AJ21: =IFERROR(AI21/E21,0) -> 0
B22: 18 | C22: Ago | D22: =VLOOKUP($B$2,BDGT_AREE!$A$1:$FT$239,BDGT_AREE!S$1,0) -> 7005.2676 | E22: =IFERROR(VLOOKUP($B$2,'18'!$A$1:$W$201,2,0),0) -> 0 | F22: =E22-D22 -> -7005.2676 | G22: =IFERROR(F22/D22,0) -> -1 | I22: =VLOOKUP($B$2,BDGT_AREE!$A$1:$FT$239,89,0) -> 332.23599 | J22: =IFERROR(VLOOKUP($B$2,'18'!$A$1:$X$201,3,0),0) -> 0 | K22: =IFERROR(VLOOKUP($B$2,'18'!$A$1:$X$201,4,0),0) -> 0 | L22: =IFERROR(K22-I22,0) -> -332.23599 | M22: =IFERROR(L22/I22,0) -> -1 | N22: =D22*Kerb_Realtime!$CD$3/Kerb_Realtime!$CE$3 -> 2.7595314 | O22: =(U22-V22)+P22 -> 104.34553 | P22: =VLOOKUP($B$2,BDGT_AREE!$A$1:$FT$239,54,0) -> 68.408498 | Q22: =IFERROR(VLOOKUP($B$2,'18'!$A$1:$W$201,5,0),0) -> 0 | R22: =IFERROR(VLOOKUP($B$2,'18'!$A$1:$W$201,6,0),0) -> 0 | S22: =R22-P22 -> -68.408498 | T22: =IFERROR(S22/P22,0) -> -1 | U22: =V22*Screen_Margini!$R$7 -> 80.402559 | V22: =P22*Kerb_BRIEFING!$Z$5 -> 44.465523 | W22: =V22/Screen_Margini!$G$17 -> 2.5807036 | X22: =P22*Kerb_BRIEFING!$AB$5 -> 12.997615 | Y22: =P22*Kerb_BRIEFING!$AC$5 -> 6.1567648 | Z22: =P22*Kerb_BRIEFING!$AD$5 -> 4.7885948 | AA22: =VLOOKUP($B$2,BDGT_AREE!$A$1:$FT$239,108,0) -> 1.3660392 | AB22: =IFERROR(VLOOKUP($B$2,'18'!$A$1:$W$201,8,0),0) -> 0 | AC22: =AB22-AA22 -> -1.3660392 | AD22: =IFERROR(AC22/AA22,0) -> -1 | AE22: =VLOOKUP($B$2,BDGT_AREE!$A$1:$FT$239,142,0) -> 0.23225806 | AF22: =IFERROR(VLOOKUP($B$2,'18'!$A$1:$W$201,7,0),0) -> 0 | AG22: =AF22-AE22 -> -0.23225806 | AH22: =IFERROR(AG22/AE22,0) -> -1 | AI22: =IFERROR(VLOOKUP($B$2,'18'!$A$1:$W$201,15,0),0) -> 0 | AJ22: =IFERROR(AI22/E22,0) -> 0
B23: 19 | C23: Ago | D23: =VLOOKUP($B$2,BDGT_AREE!$A$1:$FT$239,BDGT_AREE!T$1,0) -> 7550.9785 | E23: =IFERROR(VLOOKUP($B$2,'19'!$A$1:$W$201,2,0),0) -> 0 | F23: =E23-D23 -> -7550.9785 | G23: =IFERROR(F23/D23,0) -> -1 | I23: =VLOOKUP($B$2,BDGT_AREE!$A$1:$FT$239,90,0) -> 358.1172 | J23: =IFERROR(VLOOKUP($B$2,'19'!$A$1:$X$201,3,0),0) -> 0 | K23: =IFERROR(VLOOKUP($B$2,'19'!$A$1:$X$201,4,0),0) -> 0 | L23: =IFERROR(K23-I23,0) -> -358.1172 | M23: =IFERROR(L23/I23,0) -> -1 | N23: =D23*Kerb_Realtime!$CD$3/Kerb_Realtime!$CE$3 -> 2.9744991 | O23: =(U23-V23)+P23 -> 112.47406 | P23: =VLOOKUP($B$2,BDGT_AREE!$A$1:$FT$239,55,0) -> 73.737525 | Q23: =IFERROR(VLOOKUP($B$2,'19'!$A$1:$W$201,5,0),0) -> 0 | R23: =IFERROR(VLOOKUP($B$2,'19'!$A$1:$W$201,6,0),0) -> 0 | S23: =R23-P23 -> -73.737525 | T23: =IFERROR(S23/P23,0) -> -1 | U23: =V23*Screen_Margini!$R$7 -> 86.665926 | V23: =P23*Kerb_BRIEFING!$Z$5 -> 47.929392 | W23: =V23/Screen_Margini!$G$17 -> 2.7817407 | X23: =P23*Kerb_BRIEFING!$AB$5 -> 14.01013 | Y23: =P23*Kerb_BRIEFING!$AC$5 -> 6.6363773 | Z23: =P23*Kerb_BRIEFING!$AD$5 -> 5.1616268 | AA23: =VLOOKUP($B$2,BDGT_AREE!$A$1:$FT$239,108,0) -> 1.3660392 | AB23: =IFERROR(VLOOKUP($B$2,'19'!$A$1:$W$201,8,0),0) -> 0 | AC23: =AB23-AA23 -> -1.3660392 | AD23: =IFERROR(AC23/AA23,0) -> -1 | AE23: =VLOOKUP($B$2,BDGT_AREE!$A$1:$FT$239,142,0) -> 0.23225806 | AF23: =IFERROR(VLOOKUP($B$2,'19'!$A$1:$W$201,7,0),0) -> 0 | AG23: =AF23-AE23 -> -0.23225806 | AH23: =IFERROR(AG23/AE23,0) -> -1 | AI23: =IFERROR(VLOOKUP($B$2,'19'!$A$1:$W$201,15,0),0) -> 0 | AJ23: =IFERROR(AI23/E23,0) -> 0
B24: 20 | C24: Ago | D24: =VLOOKUP($B$2,BDGT_AREE!$A$1:$FT$239,BDGT_AREE!U$1,0) -> 7537.3117 | E24: =IFERROR(VLOOKUP($B$2,'20'!$A$1:$W$201,2,0),0) -> 0 | F24: =E24-D24 -> -7537.3117 | G24: =IFERROR(F24/D24,0) -> -1 | I24: =VLOOKUP($B$2,BDGT_AREE!$A$1:$FT$239,91,0) -> 357.46902 | J24: =IFERROR(VLOOKUP($B$2,'20'!$A$1:$X$201,3,0),0) -> 0 | K24: =IFERROR(VLOOKUP($B$2,'20'!$A$1:$X$201,4,0),0) -> 0 | L24: =IFERROR(K24-I24,0) -> -357.46902 | M24: =IFERROR(L24/I24,0) -> -1 | N24: =D24*Kerb_Realtime!$CD$3/Kerb_Realtime!$CE$3 -> 2.9691155 | O24: =(U24-V24)+P24 -> 112.27049 | P24: =VLOOKUP($B$2,BDGT_AREE!$A$1:$FT$239,56,0) -> 73.604064 | Q24: =IFERROR(VLOOKUP($B$2,'20'!$A$1:$W$201,5,0),0) -> 0 | R24: =IFERROR(VLOOKUP($B$2,'20'!$A$1:$W$201,6,0),0) -> 0 | S24: =R24-P24 -> -73.604064 | T24: =IFERROR(S24/P24,0) -> -1 | U24: =V24*Screen_Margini!$R$7 -> 86.509065 | V24: =P24*Kerb_BRIEFING!$Z$5 -> 47.842642 | W24: =V24/Screen_Margini!$G$17 -> 2.7767059 | X24: =P24*Kerb_BRIEFING!$AB$5 -> 13.984772 | Y24: =P24*Kerb_BRIEFING!$AC$5 -> 6.6243658 | Z24: =P24*Kerb_BRIEFING!$AD$5 -> 5.1522845 | AA24: =VLOOKUP($B$2,BDGT_AREE!$A$1:$FT$239,108,0) -> 1.3660392 | AB24: =IFERROR(VLOOKUP($B$2,'20'!$A$1:$W$201,8,0),0) -> 0 | AC24: =AB24-AA24 -> -1.3660392 | AD24: =IFERROR(AC24/AA24,0) -> -1 | AE24: =VLOOKUP($B$2,BDGT_AREE!$A$1:$FT$239,142,0) -> 0.23225806 | AF24: =IFERROR(VLOOKUP($B$2,'20'!$A$1:$W$201,7,0),0) -> 0 | AG24: =AF24-AE24 -> -0.23225806 | AH24: =IFERROR(AG24/AE24,0) -> -1 | AI24: =IFERROR(VLOOKUP($B$2,'20'!$A$1:$W$201,15,0),0) -> 0 | AJ24: =IFERROR(AI24/E24,0) -> 0
B25: 21 | C25: Ago | D25: =VLOOKUP($B$2,BDGT_AREE!$A$1:$FT$239,BDGT_AREE!V$1,0) -> 7583.0834 | E25: =IFERROR(VLOOKUP($B$2,'21'!$A$1:$W$201,2,0),0) -> 0 | F25: =E25-D25 -> -7583.0834 | G25: =IFERROR(F25/D25,0) -> -1 | I25: =VLOOKUP($B$2,BDGT_AREE!$A$1:$FT$239,92,0) -> 359.63982 | J25: =IFERROR(VLOOKUP($B$2,'21'!$A$1:$X$201,3,0),0) -> 0 | K25: =IFERROR(VLOOKUP($B$2,'21'!$A$1:$X$201,4,0),0) -> 0 | L25: =IFERROR(K25-I25,0) -> -359.63982 | M25: =IFERROR(L25/I25,0) -> -1 | N25: =D25*Kerb_Realtime!$CD$3/Kerb_Realtime!$CE$3 -> 2.987146 | O25: =(U25-V25)+P25 -> 112.95227 | P25: =VLOOKUP($B$2,BDGT_AREE!$A$1:$FT$239,57,0) -> 74.051039 | Q25: =IFERROR(VLOOKUP($B$2,'21'!$A$1:$W$201,5,0),0) -> 0 | R25: =IFERROR(VLOOKUP($B$2,'21'!$A$1:$W$201,6,0),0) -> 0 | S25: =R25-P25 -> -74.051039 | T25: =IFERROR(S25/P25,0) -> -1 | U25: =V25*Screen_Margini!$R$7 -> 87.034407 | V25: =P25*Kerb_BRIEFING!$Z$5 -> 48.133175 | W25: =V25/Screen_Margini!$G$17 -> 2.7935679 | X25: =P25*Kerb_BRIEFING!$AB$5 -> 14.069697 | Y25: =P25*Kerb_BRIEFING!$AC$5 -> 6.6645935 | Z25: =P25*Kerb_BRIEFING!$AD$5 -> 5.1835727 | AA25: =VLOOKUP($B$2,BDGT_AREE!$A$1:$FT$239,108,0) -> 1.3660392 | AB25: =IFERROR(VLOOKUP($B$2,'21'!$A$1:$W$201,8,0),0) -> 0 | AC25: =AB25-AA25 -> -1.3660392 | AD25: =IFERROR(AC25/AA25,0) -> -1 | AE25: =VLOOKUP($B$2,BDGT_AREE!$A$1:$FT$239,142,0) -> 0.23225806 | AF25: =IFERROR(VLOOKUP($B$2,'21'!$A$1:$W$201,7,0),0) -> 0 | AG25: =AF25-AE25 -> -0.23225806 | AH25: =IFERROR(AG25/AE25,0) -> -1 | AI25: =IFERROR(VLOOKUP($B$2,'21'!$A$1:$W$201,15,0),0) -> 0 | AJ25: =IFERROR(AI25/E25,0) -> 0
B26: 22 | C26: Ago | D26: =VLOOKUP($B$2,BDGT_AREE!$A$1:$FT$239,BDGT_AREE!W$1,0) -> 9137.0139 | E26: =IFERROR(VLOOKUP($B$2,'22'!$A$1:$W$201,2,0),0) -> 0 | F26: =E26-D26 -> -9137.0139 | G26: =IFERROR(F26/D26,0) -> -1 | I26: =VLOOKUP($B$2,BDGT_AREE!$A$1:$FT$239,93,0) -> 428.16648 | J26: =IFERROR(VLOOKUP($B$2,'22'!$A$1:$X$201,3,0),0) -> 0 | K26: =IFERROR(VLOOKUP($B$2,'22'!$A$1:$X$201,4,0),0) -> 0 | L26: =IFERROR(K26-I26,0) -> -428.16648 | M26: =IFERROR(L26/I26,0) -> -1 | N26: =D26*Kerb_Realtime!$CD$3/Kerb_Realtime!$CE$3 -> 3.5992739 | O26: =(U26-V26)+P26 -> 134.47448 | P26: =VLOOKUP($B$2,BDGT_AREE!$A$1:$FT$239,58,0) -> 88.160906 | Q26: =IFERROR(VLOOKUP($B$2,'22'!$A$1:$W$201,5,0),0) -> 0 | R26: =IFERROR(VLOOKUP($B$2,'22'!$A$1:$W$201,6,0),0) -> 0 | S26: =R26-P26 -> -88.160906 | T26: =IFERROR(S26/P26,0) -> -1 | U26: =V26*Screen_Margini!$R$7 -> 103.61816 | V26: =P26*Kerb_BRIEFING!$Z$5 -> 57.304589 | W26: =V26/Screen_Margini!$G$17 -> 3.3258612 | X26: =P26*Kerb_BRIEFING!$AB$5 -> 16.750572 | Y26: =P26*Kerb_BRIEFING!$AC$5 -> 7.9344816 | Z26: =P26*Kerb_BRIEFING!$AD$5 -> 6.1712635 | AA26: =VLOOKUP($B$2,BDGT_AREE!$A$1:$FT$239,108,0) -> 1.3660392 | AB26: =IFERROR(VLOOKUP($B$2,'22'!$A$1:$W$201,8,0),0) -> 0 | AC26: =AB26-AA26 -> -1.3660392 | AD26: =IFERROR(AC26/AA26,0) -> -1 | AE26: =VLOOKUP($B$2,BDGT_AREE!$A$1:$FT$239,142,0) -> 0.23225806 | AF26: =IFERROR(VLOOKUP($B$2,'22'!$A$1:$W$201,7,0),0) -> 0 | AG26: =AF26-AE26 -> -0.23225806 | AH26: =IFERROR(AG26/AE26,0) -> -1 | AI26: =IFERROR(VLOOKUP($B$2,'22'!$A$1:$W$201,15,0),0) -> 0 | AJ26: =IFERROR(AI26/E26,0) -> 0
B27: 23 | C27: Ago | D27: =VLOOKUP($B$2,BDGT_AREE!$A$1:$FT$239,BDGT_AREE!X$1,0) -> 8900.3203 | E27: =IFERROR(VLOOKUP($B$2,'23'!$A$1:$W$201,2,0),0) -> 0 | F27: =E27-D27 -> -8900.3203 | G27: =IFERROR(F27/D27,0) -> -1 | I27: =VLOOKUP($B$2,BDGT_AREE!$A$1:$FT$239,94,0) -> 422.11188 | J27: =IFERROR(VLOOKUP($B$2,'23'!$A$1:$X$201,3,0),0) -> 0 | K27: =IFERROR(VLOOKUP($B$2,'23'!$A$1:$X$201,4,0),0) -> 0 | L27: =IFERROR(K27-I27,0) -> -422.11188 | M27: =IFERROR(L27/I27,0) -> -1 | N27: =D27*Kerb_Realtime!$CD$3/Kerb_Realtime!$CE$3 -> 3.506035 | O27: =(U27-V27)+P27 -> 132.5729 | P27: =VLOOKUP($B$2,BDGT_AREE!$A$1:$FT$239,59,0) -> 86.914244 | Q27: =IFERROR(VLOOKUP($B$2,'23'!$A$1:$W$201,5,0),0) -> 0 | R27: =IFERROR(VLOOKUP($B$2,'23'!$A$1:$W$201,6,0),0) -> 0 | S27: =R27-P27 -> -86.914244 | T27: =IFERROR(S27/P27,0) -> -1 | U27: =V27*Screen_Margini!$R$7 -> 102.15292 | V27: =P27*Kerb_BRIEFING!$Z$5 -> 56.494259 | W27: =V27/Screen_Margini!$G$17 -> 3.278831 | X27: =P27*Kerb_BRIEFING!$AB$5 -> 16.513706 | Y27: =P27*Kerb_BRIEFING!$AC$5 -> 7.822282 | Z27: =P27*Kerb_BRIEFING!$AD$5 -> 6.0839971 | AA27: =VLOOKUP($B$2,BDGT_AREE!$A$1:$FT$239,108,0) -> 1.3660392 | AB27: =IFERROR(VLOOKUP($B$2,'23'!$A$1:$W$201,8,0),0) -> 0 | AC27: =AB27-AA27 -> -1.3660392 | AD27: =IFERROR(AC27/AA27,0) -> -1 | AE27: =VLOOKUP($B$2,BDGT_AREE!$A$1:$FT$239,142,0) -> 0.23225806 | AF27: =IFERROR(VLOOKUP($B$2,'23'!$A$1:$W$201,7,0),0) -> 0 | AG27: =AF27-AE27 -> -0.23225806 | AH27: =IFERROR(AG27/AE27,0) -> -1 | AI27: =IFERROR(VLOOKUP($B$2,'23'!$A$1:$W$201,15,0),0) -> 0 | AJ27: =IFERROR(AI27/E27,0) -> 0
B28: 24 | C28: Ago | D28: =VLOOKUP($B$2,BDGT_AREE!$A$1:$FT$239,BDGT_AREE!Y$1,0) -> 7198.1817 | E28: =IFERROR(VLOOKUP($B$2,'24'!$A$1:$W$201,2,0),0) -> 0 | F28: =E28-D28 -> -7198.1817 | G28: =IFERROR(F28/D28,0) -> -1 | I28: =VLOOKUP($B$2,BDGT_AREE!$A$1:$FT$239,95,0) -> 341.38525 | J28: =IFERROR(VLOOKUP($B$2,'24'!$A$1:$X$201,3,0),0) -> 0 | K28: =IFERROR(VLOOKUP($B$2,'24'!$A$1:$X$201,4,0),0) -> 0 | L28: =IFERROR(K28-I28,0) -> -341.38525 | M28: =IFERROR(L28/I28,0) -> -1 | N28: =D28*Kerb_Realtime!$CD$3/Kerb_Realtime!$CE$3 -> 2.8355246 | O28: =(U28-V28)+P28 -> 107.21905 | P28: =VLOOKUP($B$2,BDGT_AREE!$A$1:$FT$239,60,0) -> 70.292361 | Q28: =IFERROR(VLOOKUP($B$2,'24'!$A$1:$W$201,5,0),0) -> 0 | R28: =IFERROR(VLOOKUP($B$2,'24'!$A$1:$W$201,6,0),0) -> 0 | S28: =R28-P28 -> -70.292361 | T28: =IFERROR(S28/P28,0) -> -1 | U28: =V28*Screen_Margini!$R$7 -> 82.616721 | V28: =P28*Kerb_BRIEFING!$Z$5 -> 45.690035 | W28: =V28/Screen_Margini!$G$17 -> 2.6517722 | X28: =P28*Kerb_BRIEFING!$AB$5 -> 13.355549 | Y28: =P28*Kerb_BRIEFING!$AC$5 -> 6.3263125 | Z28: =P28*Kerb_BRIEFING!$AD$5 -> 4.9204653 | AA28: =VLOOKUP($B$2,BDGT_AREE!$A$1:$FT$239,108,0) -> 1.3660392 | AB28: =IFERROR(VLOOKUP($B$2,'24'!$A$1:$W$201,8,0),0) -> 0 | AC28: =AB28-AA28 -> -1.3660392 | AD28: =IFERROR(AC28/AA28,0) -> -1 | AE28: =VLOOKUP($B$2,BDGT_AREE!$A$1:$FT$239,142,0) -> 0.23225806 | AF28: =IFERROR(VLOOKUP($B$2,'24'!$A$1:$W$201,7,0),0) -> 0 | AG28: =AF28-AE28 -> -0.23225806 | AH28: =IFERROR(AG28/AE28,0) -> -1 | AI28: =IFERROR(VLOOKUP($B$2,'24'!$A$1:$W$201,15,0),0) -> 0 | AJ28: =IFERROR(AI28/E28,0) -> 0
B29: 25 | C29: Ago | D29: =VLOOKUP($B$2,BDGT_AREE!$A$1:$FT$239,BDGT_AREE!Z$1,0) -> 6832.4961 | E29: =IFERROR(VLOOKUP($B$2,'25'!$A$1:$W$201,2,0),0) -> 0 | F29: =E29-D29 -> -6832.4961 | G29: =IFERROR(F29/D29,0) -> -1 | I29: =VLOOKUP($B$2,BDGT_AREE!$A$1:$FT$239,96,0) -> 324.04202 | J29: =IFERROR(VLOOKUP($B$2,'25'!$A$1:$X$201,3,0),0) -> 0 | K29: =IFERROR(VLOOKUP($B$2,'25'!$A$1:$X$201,4,0),0) -> 0 | L29: =IFERROR(K29-I29,0) -> -324.04202 | M29: =IFERROR(L29/I29,0) -> -1 | N29: =D29*Kerb_Realtime!$CD$3/Kerb_Realtime!$CE$3 -> 2.6914729 | O29: =(U29-V29)+P29 -> 101.77205 | P29: =VLOOKUP($B$2,BDGT_AREE!$A$1:$FT$239,61,0) -> 66.721333 | Q29: =IFERROR(VLOOKUP($B$2,'25'!$A$1:$W$201,5,0),0) -> 0 | R29: =IFERROR(VLOOKUP($B$2,'25'!$A$1:$W$201,6,0),0) -> 0 | S29: =R29-P29 -> -66.721333 | T29: =IFERROR(S29/P29,0) -> -1 | U29: =V29*Screen_Margini!$R$7 -> 78.419584 | V29: =P29*Kerb_BRIEFING!$Z$5 -> 43.368867 | W29: =V29/Screen_Margini!$G$17 -> 2.5170555 | X29: =P29*Kerb_BRIEFING!$AB$5 -> 12.677053 | Y29: =P29*Kerb_BRIEFING!$AC$5 -> 6.00492 | Z29: =P29*Kerb_BRIEFING!$AD$5 -> 4.6704933 | AA29: =VLOOKUP($B$2,BDGT_AREE!$A$1:$FT$239,108,0) -> 1.3660392 | AB29: =IFERROR(VLOOKUP($B$2,'25'!$A$1:$W$201,8,0),0) -> 0 | AC29: =AB29-AA29 -> -1.3660392 | AD29: =IFERROR(AC29/AA29,0) -> -1 | AE29: =VLOOKUP($B$2,BDGT_AREE!$A$1:$FT$239,142,0) -> 0.23225806 | AF29: =IFERROR(VLOOKUP($B$2,'25'!$A$1:$W$201,7,0),0) -> 0 | AG29: =AF29-AE29 -> -0.23225806 | AH29: =IFERROR(AG29/AE29,0) -> -1 | AI29: =IFERROR(VLOOKUP($B$2,'25'!$A$1:$W$201,15,0),0) -> 0 | AJ29: =IFERROR(AI29/E29,0) -> 0
B30: 26 | C30: Ago | D30: =VLOOKUP($B$2,BDGT_AREE!$A$1:$FT$239,BDGT_AREE!AA$1,0) -> 7203.1893 | E30: =IFERROR(VLOOKUP($B$2,'26'!$A$1:$W$201,2,0),0) -> 0 | F30: =E30-D30 -> -7203.1893 | G30: =IFERROR(F30/D30,0) -> -1 | I30: =VLOOKUP($B$2,BDGT_AREE!$A$1:$FT$239,97,0) -> 341.62274 | J30: =IFERROR(VLOOKUP($B$2,'26'!$A$1:$X$201,3,0),0) -> 0 | K30: =IFERROR(VLOOKUP($B$2,'26'!$A$1:$X$201,4,0),0) -> 0 | L30: =IFERROR(K30-I30,0) -> -341.62274 | M30: =IFERROR(L30/I30,0) -> -1 | N30: =D30*Kerb_Realtime!$CD$3/Kerb_Realtime!$CE$3 -> 2.8374972 | O30: =(U30-V30)+P30 -> 107.29364 | P30: =VLOOKUP($B$2,BDGT_AREE!$A$1:$FT$239,62,0) -> 70.341261 | Q30: =IFERROR(VLOOKUP($B$2,'26'!$A$1:$W$201,5,0),0) -> 0 | R30: =IFERROR(VLOOKUP($B$2,'26'!$A$1:$W$201,6,0),0) -> 0 | S30: =R30-P30 -> -70.341261 | T30: =IFERROR(S30/P30,0) -> -1 | U30: =V30*Screen_Margini!$R$7 -> 82.674194 | V30: =P30*Kerb_BRIEFING!$Z$5 -> 45.72182 | W30: =V30/Screen_Margini!$G$17 -> 2.6536169 | X30: =P30*Kerb_BRIEFING!$AB$5 -> 13.36484 | Y30: =P30*Kerb_BRIEFING!$AC$5 -> 6.3307135 | Z30: =P30*Kerb_BRIEFING!$AD$5 -> 4.9238883 | AA30: =VLOOKUP($B$2,BDGT_AREE!$A$1:$FT$239,108,0) -> 1.3660392 | AB30: =IFERROR(VLOOKUP($B$2,'26'!$A$1:$W$201,8,0),0) -> 0 | AC30: =AB30-AA30 -> -1.3660392 | AD30: =IFERROR(AC30/AA30,0) -> -1 | AE30: =VLOOKUP($B$2,BDGT_AREE!$A$1:$FT$239,142,0) -> 0.23225806 | AF30: =IFERROR(VLOOKUP($B$2,'26'!$A$1:$W$201,7,0),0) -> 0 | AG30: =AF30-AE30 -> -0.23225806 | AH30: =IFERROR(AG30/AE30,0) -> -1 | AI30: =IFERROR(VLOOKUP($B$2,'26'!$A$1:$W$201,15,0),0) -> 0 | AJ30: =IFERROR(AI30/E30,0) -> 0
B31: 27 | C31: Ago | D31: =VLOOKUP($B$2,BDGT_AREE!$A$1:$FT$239,BDGT_AREE!AB$1,0) -> 7262.5529 | E31: =IFERROR(VLOOKUP($B$2,'27'!$A$1:$W$201,2,0),0) -> 0 | F31: =E31-D31 -> -7262.5529 | G31: =IFERROR(F31/D31,0) -> -1 | I31: =VLOOKUP($B$2,BDGT_AREE!$A$1:$FT$239,98,0) -> 344.43815 | J31: =IFERROR(VLOOKUP($B$2,'27'!$A$1:$X$201,3,0),0) -> 0 | K31: =IFERROR(VLOOKUP($B$2,'27'!$A$1:$X$201,4,0),0) -> 0 | L31: =IFERROR(K31-I31,0) -> -344.43815 | M31: =IFERROR(L31/I31,0) -> -1 | N31: =D31*Kerb_Realtime!$CD$3/Kerb_Realtime!$CE$3 -> 2.8608818 | O31: =(U31-V31)+P31 -> 108.17787 | P31: =VLOOKUP($B$2,BDGT_AREE!$A$1:$FT$239,63,0) -> 70.920964 | Q31: =IFERROR(VLOOKUP($B$2,'27'!$A$1:$W$201,5,0),0) -> 0 | R31: =IFERROR(VLOOKUP($B$2,'27'!$A$1:$W$201,6,0),0) -> 0 | S31: =R31-P31 -> -70.920964 | T31: =IFERROR(S31/P31,0) -> -1 | U31: =V31*Screen_Margini!$R$7 -> 83.355537 | V31: =P31*Kerb_BRIEFING!$Z$5 -> 46.098627 | W31: =V31/Screen_Margini!$G$17 -> 2.6754862 | X31: =P31*Kerb_BRIEFING!$AB$5 -> 13.474983 | Y31: =P31*Kerb_BRIEFING!$AC$5 -> 6.3828868 | Z31: =P31*Kerb_BRIEFING!$AD$5 -> 4.9644675 | AA31: =VLOOKUP($B$2,BDGT_AREE!$A$1:$FT$239,108,0) -> 1.3660392 | AB31: =IFERROR(VLOOKUP($B$2,'27'!$A$1:$W$201,8,0),0) -> 0 | AC31: =AB31-AA31 -> -1.3660392 | AD31: =IFERROR(AC31/AA31,0) -> -1 | AE31: =VLOOKUP($B$2,BDGT_AREE!$A$1:$FT$239,142,0) -> 0.23225806 | AF31: =IFERROR(VLOOKUP($B$2,'27'!$A$1:$W$201,7,0),0) -> 0 | AG31: =AF31-AE31 -> -0.23225806 | AH31: =IFERROR(AG31/AE31,0) -> -1 | AI31: =IFERROR(VLOOKUP($B$2,'27'!$A$1:$W$201,15,0),0) -> 0 | AJ31: =IFERROR(AI31/E31,0) -> 0
